nohup: ignoring input
2025-07-16 23:01:08,476 - bot - INFO - ü§ñ Bot de Similaridade iniciado!
2025-07-16 23:01:08,476 - bot - INFO - üìä Grupo de banco de dados: -4876022857
2025-07-16 23:01:08,476 - bot - INFO - üîç Grupo de compara√ß√£o: -4802645962
2025-07-16 23:01:08,476 - bot - INFO - üîî Grupo de notifica√ß√£o: -1002807343035
2025-07-16 23:01:08,476 - bot - INFO - üìù Formato: Monospace ativado
2025-07-16 23:01:08,476 - bot - INFO - üîß Comandos dispon√≠veis: /database, /stats, /clear, /delete, /del, /threshold, /reset, /cas, /getid, /help
2025-07-16 23:01:08,519 - httpx - INFO - HTTP Request: POST https://api.telegram.org/bot7740411827:AAFl5Fb_tuntP-_KJ2TFa8IE96dSjkn9Lig/getMe "HTTP/1.1 200 OK"
2025-07-16 23:01:08,532 - httpx - INFO - HTTP Request: POST https://api.telegram.org/bot7740411827:AAFl5Fb_tuntP-_KJ2TFa8IE96dSjkn9Lig/deleteWebhook "HTTP/1.1 200 OK"
2025-07-16 23:01:08,532 - telegram.ext.Application - INFO - Application started
2025-07-16 23:01:18,571 - httpx - INFO - HTTP Request: POST https://api.telegram.org/bot7740411827:AAFl5Fb_tuntP-_KJ2TFa8IE96dSjkn9Lig/getUpdates "HTTP/1.1 200 OK"
2025-07-16 23:01:28,585 - httpx - INFO - HTTP Request: POST https://api.telegram.org/bot7740411827:AAFl5Fb_tuntP-_KJ2TFa8IE96dSjkn9Lig/getUpdates "HTTP/1.1 200 OK"
2025-07-16 23:01:38,601 - httpx - INFO - HTTP Request: POST https://api.telegram.org/bot7740411827:AAFl5Fb_tuntP-_KJ2TFa8IE96dSjkn9Lig/getUpdates "HTTP/1.1 200 OK"
2025-07-16 23:01:48,616 - httpx - INFO - HTTP Request: POST https://api.telegram.org/bot7740411827:AAFl5Fb_tuntP-_KJ2TFa8IE96dSjkn9Lig/getUpdates "HTTP/1.1 200 OK"
2025-07-16 23:01:58,632 - httpx - INFO - HTTP Request: POST https://api.telegram.org/bot7740411827:AAFl5Fb_tuntP-_KJ2TFa8IE96dSjkn9Lig/getUpdates "HTTP/1.1 200 OK"
2025-07-16 23:02:08,651 - httpx - INFO - HTTP Request: POST https://api.telegram.org/bot7740411827:AAFl5Fb_tuntP-_KJ2TFa8IE96dSjkn9Lig/getUpdates "HTTP/1.1 200 OK"
2025-07-16 23:02:17,572 - httpx - INFO - HTTP Request: POST https://api.telegram.org/bot7740411827:AAFl5Fb_tuntP-_KJ2TFa8IE96dSjkn9Lig/getUpdates "HTTP/1.1 409 Conflict"
2025-07-16 23:02:17,572 - telegram.ext.Application - ERROR - No error handlers are registered, logging exception.
Traceback (most recent call last):
  File "/usr/local/lib/python3.10/dist-packages/telegram/ext/_updater.py", line 753, in _network_loop_retry
    if not await do_action():
  File "/usr/local/lib/python3.10/dist-packages/telegram/ext/_updater.py", line 747, in do_action
    return action_cb_task.result()
  File "/usr/local/lib/python3.10/dist-packages/telegram/ext/_updater.py", line 377, in polling_action_cb
    updates = await self.bot.get_updates(
  File "/usr/local/lib/python3.10/dist-packages/telegram/ext/_extbot.py", line 649, in get_updates
    updates = await super().get_updates(
  File "/usr/local/lib/python3.10/dist-packages/telegram/_bot.py", line 4366, in get_updates
    await self._post(
  File "/usr/local/lib/python3.10/dist-packages/telegram/_bot.py", line 623, in _post
    return await self._do_post(
  File "/usr/local/lib/python3.10/dist-packages/telegram/ext/_extbot.py", line 355, in _do_post
    return await super()._do_post(
  File "/usr/local/lib/python3.10/dist-packages/telegram/_bot.py", line 652, in _do_post
    result = await request.post(
  File "/usr/local/lib/python3.10/dist-packages/telegram/request/_baserequest.py", line 201, in post
    result = await self._request_wrapper(
  File "/usr/local/lib/python3.10/dist-packages/telegram/request/_baserequest.py", line 384, in _request_wrapper
    raise Conflict(message)
telegram.error.Conflict: Conflict: terminated by other getUpdates request; make sure that only one bot instance is running
2025-07-16 23:02:22,608 - httpx - INFO - HTTP Request: POST https://api.telegram.org/bot7740411827:AAFl5Fb_tuntP-_KJ2TFa8IE96dSjkn9Lig/getUpdates "HTTP/1.1 409 Conflict"
2025-07-16 23:02:22,608 - telegram.ext.Application - ERROR - No error handlers are registered, logging exception.
Traceback (most recent call last):
  File "/usr/local/lib/python3.10/dist-packages/telegram/ext/_updater.py", line 753, in _network_loop_retry
    if not await do_action():
  File "/usr/local/lib/python3.10/dist-packages/telegram/ext/_updater.py", line 747, in do_action
    return action_cb_task.result()
  File "/usr/local/lib/python3.10/dist-packages/telegram/ext/_updater.py", line 377, in polling_action_cb
    updates = await self.bot.get_updates(
  File "/usr/local/lib/python3.10/dist-packages/telegram/ext/_extbot.py", line 649, in get_updates
    updates = await super().get_updates(
  File "/usr/local/lib/python3.10/dist-packages/telegram/_bot.py", line 4366, in get_updates
    await self._post(
  File "/usr/local/lib/python3.10/dist-packages/telegram/_bot.py", line 623, in _post
    return await self._do_post(
  File "/usr/local/lib/python3.10/dist-packages/telegram/ext/_extbot.py", line 355, in _do_post
    return await super()._do_post(
  File "/usr/local/lib/python3.10/dist-packages/telegram/_bot.py", line 652, in _do_post
    result = await request.post(
  File "/usr/local/lib/python3.10/dist-packages/telegram/request/_baserequest.py", line 201, in post
    result = await self._request_wrapper(
  File "/usr/local/lib/python3.10/dist-packages/telegram/request/_baserequest.py", line 384, in _request_wrapper
    raise Conflict(message)
telegram.error.Conflict: Conflict: terminated by other getUpdates request; make sure that only one bot instance is running
2025-07-16 23:02:25,067 - httpx - INFO - HTTP Request: POST https://api.telegram.org/bot7740411827:AAFl5Fb_tuntP-_KJ2TFa8IE96dSjkn9Lig/getUpdates "HTTP/1.1 200 OK"
2025-07-16 23:02:25,069 - bot - INFO - Mensagem recebida no chat -4802645962
2025-07-16 23:02:25,165 - httpx - INFO - HTTP Request: POST https://api.telegram.org/bot7740411827:AAFl5Fb_tuntP-_KJ2TFa8IE96dSjkn9Lig/sendMessage "HTTP/1.1 400 Bad Request"
2025-07-16 23:02:25,165 - bot - ERROR - Erro ao enviar notifica√ß√£o para grupo de notifica√ß√£o: Can't parse entities: can't find end of the entity starting at byte offset 7069
2025-07-16 23:02:28,647 - httpx - INFO - HTTP Request: POST https://api.telegram.org/bot7740411827:AAFl5Fb_tuntP-_KJ2TFa8IE96dSjkn9Lig/getUpdates "HTTP/1.1 409 Conflict"
2025-07-16 23:02:28,647 - telegram.ext.Application - ERROR - No error handlers are registered, logging exception.
Traceback (most recent call last):
  File "/usr/local/lib/python3.10/dist-packages/telegram/ext/_updater.py", line 753, in _network_loop_retry
    if not await do_action():
  File "/usr/local/lib/python3.10/dist-packages/telegram/ext/_updater.py", line 747, in do_action
    return action_cb_task.result()
  File "/usr/local/lib/python3.10/dist-packages/telegram/ext/_updater.py", line 377, in polling_action_cb
    updates = await self.bot.get_updates(
  File "/usr/local/lib/python3.10/dist-packages/telegram/ext/_extbot.py", line 649, in get_updates
    updates = await super().get_updates(
  File "/usr/local/lib/python3.10/dist-packages/telegram/_bot.py", line 4366, in get_updates
    await self._post(
  File "/usr/local/lib/python3.10/dist-packages/telegram/_bot.py", line 623, in _post
    return await self._do_post(
  File "/usr/local/lib/python3.10/dist-packages/telegram/ext/_extbot.py", line 355, in _do_post
    return await super()._do_post(
  File "/usr/local/lib/python3.10/dist-packages/telegram/_bot.py", line 652, in _do_post
    result = await request.post(
  File "/usr/local/lib/python3.10/dist-packages/telegram/request/_baserequest.py", line 201, in post
    result = await self._request_wrapper(
  File "/usr/local/lib/python3.10/dist-packages/telegram/request/_baserequest.py", line 384, in _request_wrapper
    raise Conflict(message)
telegram.error.Conflict: Conflict: terminated by other getUpdates request; make sure that only one bot instance is running
2025-07-16 23:02:34,940 - httpx - INFO - HTTP Request: POST https://api.telegram.org/bot7740411827:AAFl5Fb_tuntP-_KJ2TFa8IE96dSjkn9Lig/getUpdates "HTTP/1.1 409 Conflict"
2025-07-16 23:02:34,941 - telegram.ext.Application - ERROR - No error handlers are registered, logging exception.
Traceback (most recent call last):
  File "/usr/local/lib/python3.10/dist-packages/telegram/ext/_updater.py", line 753, in _network_loop_retry
    if not await do_action():
  File "/usr/local/lib/python3.10/dist-packages/telegram/ext/_updater.py", line 747, in do_action
    return action_cb_task.result()
  File "/usr/local/lib/python3.10/dist-packages/telegram/ext/_updater.py", line 377, in polling_action_cb
    updates = await self.bot.get_updates(
  File "/usr/local/lib/python3.10/dist-packages/telegram/ext/_extbot.py", line 649, in get_updates
    updates = await super().get_updates(
  File "/usr/local/lib/python3.10/dist-packages/telegram/_bot.py", line 4366, in get_updates
    await self._post(
  File "/usr/local/lib/python3.10/dist-packages/telegram/_bot.py", line 623, in _post
    return await self._do_post(
  File "/usr/local/lib/python3.10/dist-packages/telegram/ext/_extbot.py", line 355, in _do_post
    return await super()._do_post(
  File "/usr/local/lib/python3.10/dist-packages/telegram/_bot.py", line 652, in _do_post
    result = await request.post(
  File "/usr/local/lib/python3.10/dist-packages/telegram/request/_baserequest.py", line 201, in post
    result = await self._request_wrapper(
  File "/usr/local/lib/python3.10/dist-packages/telegram/request/_baserequest.py", line 384, in _request_wrapper
    raise Conflict(message)
telegram.error.Conflict: Conflict: terminated by other getUpdates request; make sure that only one bot instance is running
2025-07-16 23:02:40,052 - httpx - INFO - HTTP Request: POST https://api.telegram.org/bot7740411827:AAFl5Fb_tuntP-_KJ2TFa8IE96dSjkn9Lig/getUpdates "HTTP/1.1 200 OK"
2025-07-16 23:02:40,319 - httpx - INFO - HTTP Request: POST https://api.telegram.org/bot7740411827:AAFl5Fb_tuntP-_KJ2TFa8IE96dSjkn9Lig/sendMessage "HTTP/1.1 200 OK"
2025-07-16 23:02:42,848 - httpx - INFO - HTTP Request: POST https://api.telegram.org/bot7740411827:AAFl5Fb_tuntP-_KJ2TFa8IE96dSjkn9Lig/getUpdates "HTTP/1.1 409 Conflict"
2025-07-16 23:02:42,848 - telegram.ext.Application - ERROR - No error handlers are registered, logging exception.
Traceback (most recent call last):
  File "/usr/local/lib/python3.10/dist-packages/telegram/ext/_updater.py", line 753, in _network_loop_retry
    if not await do_action():
  File "/usr/local/lib/python3.10/dist-packages/telegram/ext/_updater.py", line 747, in do_action
    return action_cb_task.result()
  File "/usr/local/lib/python3.10/dist-packages/telegram/ext/_updater.py", line 377, in polling_action_cb
    updates = await self.bot.get_updates(
  File "/usr/local/lib/python3.10/dist-packages/telegram/ext/_extbot.py", line 649, in get_updates
    updates = await super().get_updates(
  File "/usr/local/lib/python3.10/dist-packages/telegram/_bot.py", line 4366, in get_updates
    await self._post(
  File "/usr/local/lib/python3.10/dist-packages/telegram/_bot.py", line 623, in _post
    return await self._do_post(
  File "/usr/local/lib/python3.10/dist-packages/telegram/ext/_extbot.py", line 355, in _do_post
    return await super()._do_post(
  File "/usr/local/lib/python3.10/dist-packages/telegram/_bot.py", line 652, in _do_post
    result = await request.post(
  File "/usr/local/lib/python3.10/dist-packages/telegram/request/_baserequest.py", line 201, in post
    result = await self._request_wrapper(
  File "/usr/local/lib/python3.10/dist-packages/telegram/request/_baserequest.py", line 384, in _request_wrapper
    raise Conflict(message)
telegram.error.Conflict: Conflict: terminated by other getUpdates request; make sure that only one bot instance is running
2025-07-16 23:02:51,975 - httpx - INFO - HTTP Request: POST https://api.telegram.org/bot7740411827:AAFl5Fb_tuntP-_KJ2TFa8IE96dSjkn9Lig/getUpdates "HTTP/1.1 409 Conflict"
2025-07-16 23:02:51,975 - telegram.ext.Application - ERROR - No error handlers are registered, logging exception.
Traceback (most recent call last):
  File "/usr/local/lib/python3.10/dist-packages/telegram/ext/_updater.py", line 753, in _network_loop_retry
    if not await do_action():
  File "/usr/local/lib/python3.10/dist-packages/telegram/ext/_updater.py", line 747, in do_action
    return action_cb_task.result()
  File "/usr/local/lib/python3.10/dist-packages/telegram/ext/_updater.py", line 377, in polling_action_cb
    updates = await self.bot.get_updates(
  File "/usr/local/lib/python3.10/dist-packages/telegram/ext/_extbot.py", line 649, in get_updates
    updates = await super().get_updates(
  File "/usr/local/lib/python3.10/dist-packages/telegram/_bot.py", line 4366, in get_updates
    await self._post(
  File "/usr/local/lib/python3.10/dist-packages/telegram/_bot.py", line 623, in _post
    return await self._do_post(
  File "/usr/local/lib/python3.10/dist-packages/telegram/ext/_extbot.py", line 355, in _do_post
    return await super()._do_post(
  File "/usr/local/lib/python3.10/dist-packages/telegram/_bot.py", line 652, in _do_post
    result = await request.post(
  File "/usr/local/lib/python3.10/dist-packages/telegram/request/_baserequest.py", line 201, in post
    result = await self._request_wrapper(
  File "/usr/local/lib/python3.10/dist-packages/telegram/request/_baserequest.py", line 384, in _request_wrapper
    raise Conflict(message)
telegram.error.Conflict: Conflict: terminated by other getUpdates request; make sure that only one bot instance is running
2025-07-16 23:03:02,673 - httpx - INFO - HTTP Request: POST https://api.telegram.org/bot7740411827:AAFl5Fb_tuntP-_KJ2TFa8IE96dSjkn9Lig/getUpdates "HTTP/1.1 200 OK"
2025-07-16 23:03:02,857 - httpx - INFO - HTTP Request: POST https://api.telegram.org/bot7740411827:AAFl5Fb_tuntP-_KJ2TFa8IE96dSjkn9Lig/sendMessage "HTTP/1.1 200 OK"
2025-07-16 23:03:04,149 - httpx - INFO - HTTP Request: POST https://api.telegram.org/bot7740411827:AAFl5Fb_tuntP-_KJ2TFa8IE96dSjkn9Lig/getUpdates "HTTP/1.1 409 Conflict"
2025-07-16 23:03:04,150 - telegram.ext.Application - ERROR - No error handlers are registered, logging exception.
Traceback (most recent call last):
  File "/usr/local/lib/python3.10/dist-packages/telegram/ext/_updater.py", line 753, in _network_loop_retry
    if not await do_action():
  File "/usr/local/lib/python3.10/dist-packages/telegram/ext/_updater.py", line 747, in do_action
    return action_cb_task.result()
  File "/usr/local/lib/python3.10/dist-packages/telegram/ext/_updater.py", line 377, in polling_action_cb
    updates = await self.bot.get_updates(
  File "/usr/local/lib/python3.10/dist-packages/telegram/ext/_extbot.py", line 649, in get_updates
    updates = await super().get_updates(
  File "/usr/local/lib/python3.10/dist-packages/telegram/_bot.py", line 4366, in get_updates
    await self._post(
  File "/usr/local/lib/python3.10/dist-packages/telegram/_bot.py", line 623, in _post
    return await self._do_post(
  File "/usr/local/lib/python3.10/dist-packages/telegram/ext/_extbot.py", line 355, in _do_post
    return await super()._do_post(
  File "/usr/local/lib/python3.10/dist-packages/telegram/_bot.py", line 652, in _do_post
    result = await request.post(
  File "/usr/local/lib/python3.10/dist-packages/telegram/request/_baserequest.py", line 201, in post
    result = await self._request_wrapper(
  File "/usr/local/lib/python3.10/dist-packages/telegram/request/_baserequest.py", line 384, in _request_wrapper
    raise Conflict(message)
telegram.error.Conflict: Conflict: terminated by other getUpdates request; make sure that only one bot instance is running
2025-07-16 23:03:08,463 - httpx - INFO - HTTP Request: POST https://api.telegram.org/bot7740411827:AAFl5Fb_tuntP-_KJ2TFa8IE96dSjkn9Lig/getUpdates "HTTP/1.1 200 OK"
2025-07-16 23:03:08,466 - bot - INFO - Mensagem recebida no chat -4876022857
2025-07-16 23:03:08,505 - bot - INFO - Token salvo no banco de dados: Worthless Coin
2025-07-16 23:03:08,670 - httpx - INFO - HTTP Request: POST https://api.telegram.org/bot7740411827:AAFl5Fb_tuntP-_KJ2TFa8IE96dSjkn9Lig/sendMessage "HTTP/1.1 200 OK"
2025-07-16 23:03:18,521 - httpx - INFO - HTTP Request: POST https://api.telegram.org/bot7740411827:AAFl5Fb_tuntP-_KJ2TFa8IE96dSjkn9Lig/getUpdates "HTTP/1.1 200 OK"
2025-07-16 23:03:19,616 - httpx - INFO - HTTP Request: POST https://api.telegram.org/bot7740411827:AAFl5Fb_tuntP-_KJ2TFa8IE96dSjkn9Lig/getUpdates "HTTP/1.1 409 Conflict"
2025-07-16 23:03:19,617 - telegram.ext.Application - ERROR - No error handlers are registered, logging exception.
Traceback (most recent call last):
  File "/usr/local/lib/python3.10/dist-packages/telegram/ext/_updater.py", line 753, in _network_loop_retry
    if not await do_action():
  File "/usr/local/lib/python3.10/dist-packages/telegram/ext/_updater.py", line 747, in do_action
    return action_cb_task.result()
  File "/usr/local/lib/python3.10/dist-packages/telegram/ext/_updater.py", line 377, in polling_action_cb
    updates = await self.bot.get_updates(
  File "/usr/local/lib/python3.10/dist-packages/telegram/ext/_extbot.py", line 649, in get_updates
    updates = await super().get_updates(
  File "/usr/local/lib/python3.10/dist-packages/telegram/_bot.py", line 4366, in get_updates
    await self._post(
  File "/usr/local/lib/python3.10/dist-packages/telegram/_bot.py", line 623, in _post
    return await self._do_post(
  File "/usr/local/lib/python3.10/dist-packages/telegram/ext/_extbot.py", line 355, in _do_post
    return await super()._do_post(
  File "/usr/local/lib/python3.10/dist-packages/telegram/_bot.py", line 652, in _do_post
    result = await request.post(
  File "/usr/local/lib/python3.10/dist-packages/telegram/request/_baserequest.py", line 201, in post
    result = await self._request_wrapper(
  File "/usr/local/lib/python3.10/dist-packages/telegram/request/_baserequest.py", line 384, in _request_wrapper
    raise Conflict(message)
telegram.error.Conflict: Conflict: terminated by other getUpdates request; make sure that only one bot instance is running
2025-07-16 23:03:25,119 - httpx - INFO - HTTP Request: POST https://api.telegram.org/bot7740411827:AAFl5Fb_tuntP-_KJ2TFa8IE96dSjkn9Lig/getUpdates "HTTP/1.1 200 OK"
2025-07-16 23:03:25,121 - bot - INFO - Mensagem recebida no chat -4802645962
2025-07-16 23:03:35,139 - httpx - INFO - HTTP Request: POST https://api.telegram.org/bot7740411827:AAFl5Fb_tuntP-_KJ2TFa8IE96dSjkn9Lig/getUpdates "HTTP/1.1 200 OK"
2025-07-16 23:03:40,782 - httpx - INFO - HTTP Request: POST https://api.telegram.org/bot7740411827:AAFl5Fb_tuntP-_KJ2TFa8IE96dSjkn9Lig/getUpdates "HTTP/1.1 409 Conflict"
2025-07-16 23:03:40,783 - telegram.ext.Application - ERROR - No error handlers are registered, logging exception.
Traceback (most recent call last):
  File "/usr/local/lib/python3.10/dist-packages/telegram/ext/_updater.py", line 753, in _network_loop_retry
    if not await do_action():
  File "/usr/local/lib/python3.10/dist-packages/telegram/ext/_updater.py", line 747, in do_action
    return action_cb_task.result()
  File "/usr/local/lib/python3.10/dist-packages/telegram/ext/_updater.py", line 377, in polling_action_cb
    updates = await self.bot.get_updates(
  File "/usr/local/lib/python3.10/dist-packages/telegram/ext/_extbot.py", line 649, in get_updates
    updates = await super().get_updates(
  File "/usr/local/lib/python3.10/dist-packages/telegram/_bot.py", line 4366, in get_updates
    await self._post(
  File "/usr/local/lib/python3.10/dist-packages/telegram/_bot.py", line 623, in _post
    return await self._do_post(
  File "/usr/local/lib/python3.10/dist-packages/telegram/ext/_extbot.py", line 355, in _do_post
    return await super()._do_post(
  File "/usr/local/lib/python3.10/dist-packages/telegram/_bot.py", line 652, in _do_post
    result = await request.post(
  File "/usr/local/lib/python3.10/dist-packages/telegram/request/_baserequest.py", line 201, in post
    result = await self._request_wrapper(
  File "/usr/local/lib/python3.10/dist-packages/telegram/request/_baserequest.py", line 384, in _request_wrapper
    raise Conflict(message)
telegram.error.Conflict: Conflict: terminated by other getUpdates request; make sure that only one bot instance is running
2025-07-16 23:03:45,802 - httpx - INFO - HTTP Request: POST https://api.telegram.org/bot7740411827:AAFl5Fb_tuntP-_KJ2TFa8IE96dSjkn9Lig/getUpdates "HTTP/1.1 200 OK"
2025-07-16 23:03:45,805 - bot - INFO - Mensagem recebida no chat -1002725981594
2025-07-16 23:03:48,141 - httpx - INFO - HTTP Request: POST https://api.telegram.org/bot7740411827:AAFl5Fb_tuntP-_KJ2TFa8IE96dSjkn9Lig/getUpdates "HTTP/1.1 200 OK"
2025-07-16 23:03:48,353 - httpx - INFO - HTTP Request: POST https://api.telegram.org/bot7740411827:AAFl5Fb_tuntP-_KJ2TFa8IE96dSjkn9Lig/sendMessage "HTTP/1.1 200 OK"
2025-07-16 23:03:58,186 - httpx - INFO - HTTP Request: POST https://api.telegram.org/bot7740411827:AAFl5Fb_tuntP-_KJ2TFa8IE96dSjkn9Lig/getUpdates "HTTP/1.1 200 OK"
2025-07-16 23:03:58,949 - httpx - INFO - HTTP Request: POST https://api.telegram.org/bot7740411827:AAFl5Fb_tuntP-_KJ2TFa8IE96dSjkn9Lig/getUpdates "HTTP/1.1 200 OK"
2025-07-16 23:03:58,952 - bot - INFO - Mensagem recebida no chat -4802645962
2025-07-16 23:04:07,494 - httpx - INFO - HTTP Request: POST https://api.telegram.org/bot7740411827:AAFl5Fb_tuntP-_KJ2TFa8IE96dSjkn9Lig/getUpdates "HTTP/1.1 200 OK"
2025-07-16 23:04:07,497 - bot - INFO - Mensagem recebida no chat -4802645962
2025-07-16 23:04:07,588 - httpx - INFO - HTTP Request: POST https://api.telegram.org/bot7740411827:AAFl5Fb_tuntP-_KJ2TFa8IE96dSjkn9Lig/sendMessage "HTTP/1.1 400 Bad Request"
2025-07-16 23:04:07,588 - bot - ERROR - Erro ao enviar notifica√ß√£o para grupo de notifica√ß√£o: Can't parse entities: can't find end of the entity starting at byte offset 7069
2025-07-16 23:04:10,490 - httpx - INFO - HTTP Request: POST https://api.telegram.org/bot7740411827:AAFl5Fb_tuntP-_KJ2TFa8IE96dSjkn9Lig/getUpdates "HTTP/1.1 409 Conflict"
2025-07-16 23:04:10,490 - telegram.ext.Application - ERROR - No error handlers are registered, logging exception.
Traceback (most recent call last):
  File "/usr/local/lib/python3.10/dist-packages/telegram/ext/_updater.py", line 753, in _network_loop_retry
    if not await do_action():
  File "/usr/local/lib/python3.10/dist-packages/telegram/ext/_updater.py", line 747, in do_action
    return action_cb_task.result()
  File "/usr/local/lib/python3.10/dist-packages/telegram/ext/_updater.py", line 377, in polling_action_cb
    updates = await self.bot.get_updates(
  File "/usr/local/lib/python3.10/dist-packages/telegram/ext/_extbot.py", line 649, in get_updates
    updates = await super().get_updates(
  File "/usr/local/lib/python3.10/dist-packages/telegram/_bot.py", line 4366, in get_updates
    await self._post(
  File "/usr/local/lib/python3.10/dist-packages/telegram/_bot.py", line 623, in _post
    return await self._do_post(
  File "/usr/local/lib/python3.10/dist-packages/telegram/ext/_extbot.py", line 355, in _do_post
    return await super()._do_post(
  File "/usr/local/lib/python3.10/dist-packages/telegram/_bot.py", line 652, in _do_post
    result = await request.post(
  File "/usr/local/lib/python3.10/dist-packages/telegram/request/_baserequest.py", line 201, in post
    result = await self._request_wrapper(
  File "/usr/local/lib/python3.10/dist-packages/telegram/request/_baserequest.py", line 384, in _request_wrapper
    raise Conflict(message)
telegram.error.Conflict: Conflict: terminated by other getUpdates request; make sure that only one bot instance is running
2025-07-16 23:04:21,508 - httpx - INFO - HTTP Request: POST https://api.telegram.org/bot7740411827:AAFl5Fb_tuntP-_KJ2TFa8IE96dSjkn9Lig/getUpdates "HTTP/1.1 200 OK"
2025-07-16 23:04:31,524 - httpx - INFO - HTTP Request: POST https://api.telegram.org/bot7740411827:AAFl5Fb_tuntP-_KJ2TFa8IE96dSjkn9Lig/getUpdates "HTTP/1.1 200 OK"
2025-07-16 23:04:41,540 - httpx - INFO - HTTP Request: POST https://api.telegram.org/bot7740411827:AAFl5Fb_tuntP-_KJ2TFa8IE96dSjkn9Lig/getUpdates "HTTP/1.1 200 OK"
2025-07-16 23:04:44,583 - httpx - INFO - HTTP Request: POST https://api.telegram.org/bot7740411827:AAFl5Fb_tuntP-_KJ2TFa8IE96dSjkn9Lig/getUpdates "HTTP/1.1 409 Conflict"
2025-07-16 23:04:44,584 - telegram.ext.Application - ERROR - No error handlers are registered, logging exception.
Traceback (most recent call last):
  File "/usr/local/lib/python3.10/dist-packages/telegram/ext/_updater.py", line 753, in _network_loop_retry
    if not await do_action():
  File "/usr/local/lib/python3.10/dist-packages/telegram/ext/_updater.py", line 747, in do_action
    return action_cb_task.result()
  File "/usr/local/lib/python3.10/dist-packages/telegram/ext/_updater.py", line 377, in polling_action_cb
    updates = await self.bot.get_updates(
  File "/usr/local/lib/python3.10/dist-packages/telegram/ext/_extbot.py", line 649, in get_updates
    updates = await super().get_updates(
  File "/usr/local/lib/python3.10/dist-packages/telegram/_bot.py", line 4366, in get_updates
    await self._post(
  File "/usr/local/lib/python3.10/dist-packages/telegram/_bot.py", line 623, in _post
    return await self._do_post(
  File "/usr/local/lib/python3.10/dist-packages/telegram/ext/_extbot.py", line 355, in _do_post
    return await super()._do_post(
  File "/usr/local/lib/python3.10/dist-packages/telegram/_bot.py", line 652, in _do_post
    result = await request.post(
  File "/usr/local/lib/python3.10/dist-packages/telegram/request/_baserequest.py", line 201, in post
    result = await self._request_wrapper(
  File "/usr/local/lib/python3.10/dist-packages/telegram/request/_baserequest.py", line 384, in _request_wrapper
    raise Conflict(message)
telegram.error.Conflict: Conflict: terminated by other getUpdates request; make sure that only one bot instance is running
2025-07-16 23:04:55,601 - httpx - INFO - HTTP Request: POST https://api.telegram.org/bot7740411827:AAFl5Fb_tuntP-_KJ2TFa8IE96dSjkn9Lig/getUpdates "HTTP/1.1 200 OK"
2025-07-16 23:05:05,616 - httpx - INFO - HTTP Request: POST https://api.telegram.org/bot7740411827:AAFl5Fb_tuntP-_KJ2TFa8IE96dSjkn9Lig/getUpdates "HTTP/1.1 200 OK"
2025-07-16 23:05:15,631 - httpx - INFO - HTTP Request: POST https://api.telegram.org/bot7740411827:AAFl5Fb_tuntP-_KJ2TFa8IE96dSjkn9Lig/getUpdates "HTTP/1.1 200 OK"
2025-07-16 23:05:19,033 - httpx - INFO - HTTP Request: POST https://api.telegram.org/bot7740411827:AAFl5Fb_tuntP-_KJ2TFa8IE96dSjkn9Lig/getUpdates "HTTP/1.1 200 OK"
2025-07-16 23:05:19,035 - bot - INFO - Mensagem recebida no chat -1002725981594
2025-07-16 23:05:29,051 - httpx - INFO - HTTP Request: POST https://api.telegram.org/bot7740411827:AAFl5Fb_tuntP-_KJ2TFa8IE96dSjkn9Lig/getUpdates "HTTP/1.1 200 OK"
2025-07-16 23:05:39,069 - httpx - INFO - HTTP Request: POST https://api.telegram.org/bot7740411827:AAFl5Fb_tuntP-_KJ2TFa8IE96dSjkn9Lig/getUpdates "HTTP/1.1 200 OK"
2025-07-16 23:05:49,085 - httpx - INFO - HTTP Request: POST https://api.telegram.org/bot7740411827:AAFl5Fb_tuntP-_KJ2TFa8IE96dSjkn9Lig/getUpdates "HTTP/1.1 200 OK"
2025-07-16 23:05:59,100 - httpx - INFO - HTTP Request: POST https://api.telegram.org/bot7740411827:AAFl5Fb_tuntP-_KJ2TFa8IE96dSjkn9Lig/getUpdates "HTTP/1.1 200 OK"
2025-07-16 23:06:09,115 - httpx - INFO - HTTP Request: POST https://api.telegram.org/bot7740411827:AAFl5Fb_tuntP-_KJ2TFa8IE96dSjkn9Lig/getUpdates "HTTP/1.1 200 OK"
2025-07-16 23:06:09,633 - httpx - INFO - HTTP Request: POST https://api.telegram.org/bot7740411827:AAFl5Fb_tuntP-_KJ2TFa8IE96dSjkn9Lig/getUpdates "HTTP/1.1 409 Conflict"
2025-07-16 23:06:09,634 - telegram.ext.Application - ERROR - No error handlers are registered, logging exception.
Traceback (most recent call last):
  File "/usr/local/lib/python3.10/dist-packages/telegram/ext/_updater.py", line 753, in _network_loop_retry
    if not await do_action():
  File "/usr/local/lib/python3.10/dist-packages/telegram/ext/_updater.py", line 747, in do_action
    return action_cb_task.result()
  File "/usr/local/lib/python3.10/dist-packages/telegram/ext/_updater.py", line 377, in polling_action_cb
    updates = await self.bot.get_updates(
  File "/usr/local/lib/python3.10/dist-packages/telegram/ext/_extbot.py", line 649, in get_updates
    updates = await super().get_updates(
  File "/usr/local/lib/python3.10/dist-packages/telegram/_bot.py", line 4366, in get_updates
    await self._post(
  File "/usr/local/lib/python3.10/dist-packages/telegram/_bot.py", line 623, in _post
    return await self._do_post(
  File "/usr/local/lib/python3.10/dist-packages/telegram/ext/_extbot.py", line 355, in _do_post
    return await super()._do_post(
  File "/usr/local/lib/python3.10/dist-packages/telegram/_bot.py", line 652, in _do_post
    result = await request.post(
  File "/usr/local/lib/python3.10/dist-packages/telegram/request/_baserequest.py", line 201, in post
    result = await self._request_wrapper(
  File "/usr/local/lib/python3.10/dist-packages/telegram/request/_baserequest.py", line 384, in _request_wrapper
    raise Conflict(message)
telegram.error.Conflict: Conflict: terminated by other getUpdates request; make sure that only one bot instance is running
2025-07-16 23:06:13,112 - httpx - INFO - HTTP Request: POST https://api.telegram.org/bot7740411827:AAFl5Fb_tuntP-_KJ2TFa8IE96dSjkn9Lig/getUpdates "HTTP/1.1 200 OK"
2025-07-16 23:06:13,114 - bot - INFO - Mensagem recebida no chat -4802645962
2025-07-16 23:06:14,674 - httpx - INFO - HTTP Request: POST https://api.telegram.org/bot7740411827:AAFl5Fb_tuntP-_KJ2TFa8IE96dSjkn9Lig/getUpdates "HTTP/1.1 409 Conflict"
2025-07-16 23:06:14,674 - telegram.ext.Application - ERROR - No error handlers are registered, logging exception.
Traceback (most recent call last):
  File "/usr/local/lib/python3.10/dist-packages/telegram/ext/_updater.py", line 753, in _network_loop_retry
    if not await do_action():
  File "/usr/local/lib/python3.10/dist-packages/telegram/ext/_updater.py", line 747, in do_action
    return action_cb_task.result()
  File "/usr/local/lib/python3.10/dist-packages/telegram/ext/_updater.py", line 377, in polling_action_cb
    updates = await self.bot.get_updates(
  File "/usr/local/lib/python3.10/dist-packages/telegram/ext/_extbot.py", line 649, in get_updates
    updates = await super().get_updates(
  File "/usr/local/lib/python3.10/dist-packages/telegram/_bot.py", line 4366, in get_updates
    await self._post(
  File "/usr/local/lib/python3.10/dist-packages/telegram/_bot.py", line 623, in _post
    return await self._do_post(
  File "/usr/local/lib/python3.10/dist-packages/telegram/ext/_extbot.py", line 355, in _do_post
    return await super()._do_post(
  File "/usr/local/lib/python3.10/dist-packages/telegram/_bot.py", line 652, in _do_post
    result = await request.post(
  File "/usr/local/lib/python3.10/dist-packages/telegram/request/_baserequest.py", line 201, in post
    result = await self._request_wrapper(
  File "/usr/local/lib/python3.10/dist-packages/telegram/request/_baserequest.py", line 384, in _request_wrapper
    raise Conflict(message)
telegram.error.Conflict: Conflict: terminated by other getUpdates request; make sure that only one bot instance is running
2025-07-16 23:06:20,208 - httpx - INFO - HTTP Request: POST https://api.telegram.org/bot7740411827:AAFl5Fb_tuntP-_KJ2TFa8IE96dSjkn9Lig/getUpdates "HTTP/1.1 409 Conflict"
2025-07-16 23:06:20,209 - telegram.ext.Application - ERROR - No error handlers are registered, logging exception.
Traceback (most recent call last):
  File "/usr/local/lib/python3.10/dist-packages/telegram/ext/_updater.py", line 753, in _network_loop_retry
    if not await do_action():
  File "/usr/local/lib/python3.10/dist-packages/telegram/ext/_updater.py", line 747, in do_action
    return action_cb_task.result()
  File "/usr/local/lib/python3.10/dist-packages/telegram/ext/_updater.py", line 377, in polling_action_cb
    updates = await self.bot.get_updates(
  File "/usr/local/lib/python3.10/dist-packages/telegram/ext/_extbot.py", line 649, in get_updates
    updates = await super().get_updates(
  File "/usr/local/lib/python3.10/dist-packages/telegram/_bot.py", line 4366, in get_updates
    await self._post(
  File "/usr/local/lib/python3.10/dist-packages/telegram/_bot.py", line 623, in _post
    return await self._do_post(
  File "/usr/local/lib/python3.10/dist-packages/telegram/ext/_extbot.py", line 355, in _do_post
    return await super()._do_post(
  File "/usr/local/lib/python3.10/dist-packages/telegram/_bot.py", line 652, in _do_post
    result = await request.post(
  File "/usr/local/lib/python3.10/dist-packages/telegram/request/_baserequest.py", line 201, in post
    result = await self._request_wrapper(
  File "/usr/local/lib/python3.10/dist-packages/telegram/request/_baserequest.py", line 384, in _request_wrapper
    raise Conflict(message)
telegram.error.Conflict: Conflict: terminated by other getUpdates request; make sure that only one bot instance is running
2025-07-16 23:06:26,994 - httpx - INFO - HTTP Request: POST https://api.telegram.org/bot7740411827:AAFl5Fb_tuntP-_KJ2TFa8IE96dSjkn9Lig/getUpdates "HTTP/1.1 409 Conflict"
2025-07-16 23:06:26,995 - telegram.ext.Application - ERROR - No error handlers are registered, logging exception.
Traceback (most recent call last):
  File "/usr/local/lib/python3.10/dist-packages/telegram/ext/_updater.py", line 753, in _network_loop_retry
    if not await do_action():
  File "/usr/local/lib/python3.10/dist-packages/telegram/ext/_updater.py", line 747, in do_action
    return action_cb_task.result()
  File "/usr/local/lib/python3.10/dist-packages/telegram/ext/_updater.py", line 377, in polling_action_cb
    updates = await self.bot.get_updates(
  File "/usr/local/lib/python3.10/dist-packages/telegram/ext/_extbot.py", line 649, in get_updates
    updates = await super().get_updates(
  File "/usr/local/lib/python3.10/dist-packages/telegram/_bot.py", line 4366, in get_updates
    await self._post(
  File "/usr/local/lib/python3.10/dist-packages/telegram/_bot.py", line 623, in _post
    return await self._do_post(
  File "/usr/local/lib/python3.10/dist-packages/telegram/ext/_extbot.py", line 355, in _do_post
    return await super()._do_post(
  File "/usr/local/lib/python3.10/dist-packages/telegram/_bot.py", line 652, in _do_post
    result = await request.post(
  File "/usr/local/lib/python3.10/dist-packages/telegram/request/_baserequest.py", line 201, in post
    result = await self._request_wrapper(
  File "/usr/local/lib/python3.10/dist-packages/telegram/request/_baserequest.py", line 384, in _request_wrapper
    raise Conflict(message)
telegram.error.Conflict: Conflict: terminated by other getUpdates request; make sure that only one bot instance is running
2025-07-16 23:06:35,669 - httpx - INFO - HTTP Request: POST https://api.telegram.org/bot7740411827:AAFl5Fb_tuntP-_KJ2TFa8IE96dSjkn9Lig/getUpdates "HTTP/1.1 409 Conflict"
2025-07-16 23:06:35,670 - telegram.ext.Application - ERROR - No error handlers are registered, logging exception.
Traceback (most recent call last):
  File "/usr/local/lib/python3.10/dist-packages/telegram/ext/_updater.py", line 753, in _network_loop_retry
    if not await do_action():
  File "/usr/local/lib/python3.10/dist-packages/telegram/ext/_updater.py", line 747, in do_action
    return action_cb_task.result()
  File "/usr/local/lib/python3.10/dist-packages/telegram/ext/_updater.py", line 377, in polling_action_cb
    updates = await self.bot.get_updates(
  File "/usr/local/lib/python3.10/dist-packages/telegram/ext/_extbot.py", line 649, in get_updates
    updates = await super().get_updates(
  File "/usr/local/lib/python3.10/dist-packages/telegram/_bot.py", line 4366, in get_updates
    await self._post(
  File "/usr/local/lib/python3.10/dist-packages/telegram/_bot.py", line 623, in _post
    return await self._do_post(
  File "/usr/local/lib/python3.10/dist-packages/telegram/ext/_extbot.py", line 355, in _do_post
    return await super()._do_post(
  File "/usr/local/lib/python3.10/dist-packages/telegram/_bot.py", line 652, in _do_post
    result = await request.post(
  File "/usr/local/lib/python3.10/dist-packages/telegram/request/_baserequest.py", line 201, in post
    result = await self._request_wrapper(
  File "/usr/local/lib/python3.10/dist-packages/telegram/request/_baserequest.py", line 384, in _request_wrapper
    raise Conflict(message)
telegram.error.Conflict: Conflict: terminated by other getUpdates request; make sure that only one bot instance is running
2025-07-16 23:06:44,178 - httpx - INFO - HTTP Request: POST https://api.telegram.org/bot7740411827:AAFl5Fb_tuntP-_KJ2TFa8IE96dSjkn9Lig/getUpdates "HTTP/1.1 409 Conflict"
2025-07-16 23:06:44,179 - telegram.ext.Application - ERROR - No error handlers are registered, logging exception.
Traceback (most recent call last):
  File "/usr/local/lib/python3.10/dist-packages/telegram/ext/_updater.py", line 753, in _network_loop_retry
    if not await do_action():
  File "/usr/local/lib/python3.10/dist-packages/telegram/ext/_updater.py", line 747, in do_action
    return action_cb_task.result()
  File "/usr/local/lib/python3.10/dist-packages/telegram/ext/_updater.py", line 377, in polling_action_cb
    updates = await self.bot.get_updates(
  File "/usr/local/lib/python3.10/dist-packages/telegram/ext/_extbot.py", line 649, in get_updates
    updates = await super().get_updates(
  File "/usr/local/lib/python3.10/dist-packages/telegram/_bot.py", line 4366, in get_updates
    await self._post(
  File "/usr/local/lib/python3.10/dist-packages/telegram/_bot.py", line 623, in _post
    return await self._do_post(
  File "/usr/local/lib/python3.10/dist-packages/telegram/ext/_extbot.py", line 355, in _do_post
    return await super()._do_post(
  File "/usr/local/lib/python3.10/dist-packages/telegram/_bot.py", line 652, in _do_post
    result = await request.post(
  File "/usr/local/lib/python3.10/dist-packages/telegram/request/_baserequest.py", line 201, in post
    result = await self._request_wrapper(
  File "/usr/local/lib/python3.10/dist-packages/telegram/request/_baserequest.py", line 384, in _request_wrapper
    raise Conflict(message)
telegram.error.Conflict: Conflict: terminated by other getUpdates request; make sure that only one bot instance is running
2025-07-16 23:06:53,306 - httpx - INFO - HTTP Request: POST https://api.telegram.org/bot7740411827:AAFl5Fb_tuntP-_KJ2TFa8IE96dSjkn9Lig/getUpdates "HTTP/1.1 409 Conflict"
2025-07-16 23:06:53,307 - telegram.ext.Application - ERROR - No error handlers are registered, logging exception.
Traceback (most recent call last):
  File "/usr/local/lib/python3.10/dist-packages/telegram/ext/_updater.py", line 753, in _network_loop_retry
    if not await do_action():
  File "/usr/local/lib/python3.10/dist-packages/telegram/ext/_updater.py", line 747, in do_action
    return action_cb_task.result()
  File "/usr/local/lib/python3.10/dist-packages/telegram/ext/_updater.py", line 377, in polling_action_cb
    updates = await self.bot.get_updates(
  File "/usr/local/lib/python3.10/dist-packages/telegram/ext/_extbot.py", line 649, in get_updates
    updates = await super().get_updates(
  File "/usr/local/lib/python3.10/dist-packages/telegram/_bot.py", line 4366, in get_updates
    await self._post(
  File "/usr/local/lib/python3.10/dist-packages/telegram/_bot.py", line 623, in _post
    return await self._do_post(
  File "/usr/local/lib/python3.10/dist-packages/telegram/ext/_extbot.py", line 355, in _do_post
    return await super()._do_post(
  File "/usr/local/lib/python3.10/dist-packages/telegram/_bot.py", line 652, in _do_post
    result = await request.post(
  File "/usr/local/lib/python3.10/dist-packages/telegram/request/_baserequest.py", line 201, in post
    result = await self._request_wrapper(
  File "/usr/local/lib/python3.10/dist-packages/telegram/request/_baserequest.py", line 384, in _request_wrapper
    raise Conflict(message)
telegram.error.Conflict: Conflict: terminated by other getUpdates request; make sure that only one bot instance is running
2025-07-16 23:07:04,962 - httpx - INFO - HTTP Request: POST https://api.telegram.org/bot7740411827:AAFl5Fb_tuntP-_KJ2TFa8IE96dSjkn9Lig/getUpdates "HTTP/1.1 409 Conflict"
2025-07-16 23:07:04,963 - telegram.ext.Application - ERROR - No error handlers are registered, logging exception.
Traceback (most recent call last):
  File "/usr/local/lib/python3.10/dist-packages/telegram/ext/_updater.py", line 753, in _network_loop_retry
    if not await do_action():
  File "/usr/local/lib/python3.10/dist-packages/telegram/ext/_updater.py", line 747, in do_action
    return action_cb_task.result()
  File "/usr/local/lib/python3.10/dist-packages/telegram/ext/_updater.py", line 377, in polling_action_cb
    updates = await self.bot.get_updates(
  File "/usr/local/lib/python3.10/dist-packages/telegram/ext/_extbot.py", line 649, in get_updates
    updates = await super().get_updates(
  File "/usr/local/lib/python3.10/dist-packages/telegram/_bot.py", line 4366, in get_updates
    await self._post(
  File "/usr/local/lib/python3.10/dist-packages/telegram/_bot.py", line 623, in _post
    return await self._do_post(
  File "/usr/local/lib/python3.10/dist-packages/telegram/ext/_extbot.py", line 355, in _do_post
    return await super()._do_post(
  File "/usr/local/lib/python3.10/dist-packages/telegram/_bot.py", line 652, in _do_post
    result = await request.post(
  File "/usr/local/lib/python3.10/dist-packages/telegram/request/_baserequest.py", line 201, in post
    result = await self._request_wrapper(
  File "/usr/local/lib/python3.10/dist-packages/telegram/request/_baserequest.py", line 384, in _request_wrapper
    raise Conflict(message)
telegram.error.Conflict: Conflict: terminated by other getUpdates request; make sure that only one bot instance is running
2025-07-16 23:07:20,422 - httpx - INFO - HTTP Request: POST https://api.telegram.org/bot7740411827:AAFl5Fb_tuntP-_KJ2TFa8IE96dSjkn9Lig/getUpdates "HTTP/1.1 409 Conflict"
2025-07-16 23:07:20,423 - telegram.ext.Application - ERROR - No error handlers are registered, logging exception.
Traceback (most recent call last):
  File "/usr/local/lib/python3.10/dist-packages/telegram/ext/_updater.py", line 753, in _network_loop_retry
    if not await do_action():
  File "/usr/local/lib/python3.10/dist-packages/telegram/ext/_updater.py", line 747, in do_action
    return action_cb_task.result()
  File "/usr/local/lib/python3.10/dist-packages/telegram/ext/_updater.py", line 377, in polling_action_cb
    updates = await self.bot.get_updates(
  File "/usr/local/lib/python3.10/dist-packages/telegram/ext/_extbot.py", line 649, in get_updates
    updates = await super().get_updates(
  File "/usr/local/lib/python3.10/dist-packages/telegram/_bot.py", line 4366, in get_updates
    await self._post(
  File "/usr/local/lib/python3.10/dist-packages/telegram/_bot.py", line 623, in _post
    return await self._do_post(
  File "/usr/local/lib/python3.10/dist-packages/telegram/ext/_extbot.py", line 355, in _do_post
    return await super()._do_post(
  File "/usr/local/lib/python3.10/dist-packages/telegram/_bot.py", line 652, in _do_post
    result = await request.post(
  File "/usr/local/lib/python3.10/dist-packages/telegram/request/_baserequest.py", line 201, in post
    result = await self._request_wrapper(
  File "/usr/local/lib/python3.10/dist-packages/telegram/request/_baserequest.py", line 384, in _request_wrapper
    raise Conflict(message)
telegram.error.Conflict: Conflict: terminated by other getUpdates request; make sure that only one bot instance is running
2025-07-16 23:07:41,618 - httpx - INFO - HTTP Request: POST https://api.telegram.org/bot7740411827:AAFl5Fb_tuntP-_KJ2TFa8IE96dSjkn9Lig/getUpdates "HTTP/1.1 409 Conflict"
2025-07-16 23:07:41,619 - telegram.ext.Application - ERROR - No error handlers are registered, logging exception.
Traceback (most recent call last):
  File "/usr/local/lib/python3.10/dist-packages/telegram/ext/_updater.py", line 753, in _network_loop_retry
    if not await do_action():
  File "/usr/local/lib/python3.10/dist-packages/telegram/ext/_updater.py", line 747, in do_action
    return action_cb_task.result()
  File "/usr/local/lib/python3.10/dist-packages/telegram/ext/_updater.py", line 377, in polling_action_cb
    updates = await self.bot.get_updates(
  File "/usr/local/lib/python3.10/dist-packages/telegram/ext/_extbot.py", line 649, in get_updates
    updates = await super().get_updates(
  File "/usr/local/lib/python3.10/dist-packages/telegram/_bot.py", line 4366, in get_updates
    await self._post(
  File "/usr/local/lib/python3.10/dist-packages/telegram/_bot.py", line 623, in _post
    return await self._do_post(
  File "/usr/local/lib/python3.10/dist-packages/telegram/ext/_extbot.py", line 355, in _do_post
    return await super()._do_post(
  File "/usr/local/lib/python3.10/dist-packages/telegram/_bot.py", line 652, in _do_post
    result = await request.post(
  File "/usr/local/lib/python3.10/dist-packages/telegram/request/_baserequest.py", line 201, in post
    result = await self._request_wrapper(
  File "/usr/local/lib/python3.10/dist-packages/telegram/request/_baserequest.py", line 384, in _request_wrapper
    raise Conflict(message)
telegram.error.Conflict: Conflict: terminated by other getUpdates request; make sure that only one bot instance is running
2025-07-16 23:08:11,330 - httpx - INFO - HTTP Request: POST https://api.telegram.org/bot7740411827:AAFl5Fb_tuntP-_KJ2TFa8IE96dSjkn9Lig/getUpdates "HTTP/1.1 409 Conflict"
2025-07-16 23:08:11,330 - telegram.ext.Application - ERROR - No error handlers are registered, logging exception.
Traceback (most recent call last):
  File "/usr/local/lib/python3.10/dist-packages/telegram/ext/_updater.py", line 753, in _network_loop_retry
    if not await do_action():
  File "/usr/local/lib/python3.10/dist-packages/telegram/ext/_updater.py", line 747, in do_action
    return action_cb_task.result()
  File "/usr/local/lib/python3.10/dist-packages/telegram/ext/_updater.py", line 377, in polling_action_cb
    updates = await self.bot.get_updates(
  File "/usr/local/lib/python3.10/dist-packages/telegram/ext/_extbot.py", line 649, in get_updates
    updates = await super().get_updates(
  File "/usr/local/lib/python3.10/dist-packages/telegram/_bot.py", line 4366, in get_updates
    await self._post(
  File "/usr/local/lib/python3.10/dist-packages/telegram/_bot.py", line 623, in _post
    return await self._do_post(
  File "/usr/local/lib/python3.10/dist-packages/telegram/ext/_extbot.py", line 355, in _do_post
    return await super()._do_post(
  File "/usr/local/lib/python3.10/dist-packages/telegram/_bot.py", line 652, in _do_post
    result = await request.post(
  File "/usr/local/lib/python3.10/dist-packages/telegram/request/_baserequest.py", line 201, in post
    result = await self._request_wrapper(
  File "/usr/local/lib/python3.10/dist-packages/telegram/request/_baserequest.py", line 384, in _request_wrapper
    raise Conflict(message)
telegram.error.Conflict: Conflict: terminated by other getUpdates request; make sure that only one bot instance is running
2025-07-16 23:08:45,420 - httpx - INFO - HTTP Request: POST https://api.telegram.org/bot7740411827:AAFl5Fb_tuntP-_KJ2TFa8IE96dSjkn9Lig/getUpdates "HTTP/1.1 409 Conflict"
2025-07-16 23:08:45,421 - telegram.ext.Application - ERROR - No error handlers are registered, logging exception.
Traceback (most recent call last):
  File "/usr/local/lib/python3.10/dist-packages/telegram/ext/_updater.py", line 753, in _network_loop_retry
    if not await do_action():
  File "/usr/local/lib/python3.10/dist-packages/telegram/ext/_updater.py", line 747, in do_action
    return action_cb_task.result()
  File "/usr/local/lib/python3.10/dist-packages/telegram/ext/_updater.py", line 377, in polling_action_cb
    updates = await self.bot.get_updates(
  File "/usr/local/lib/python3.10/dist-packages/telegram/ext/_extbot.py", line 649, in get_updates
    updates = await super().get_updates(
  File "/usr/local/lib/python3.10/dist-packages/telegram/_bot.py", line 4366, in get_updates
    await self._post(
  File "/usr/local/lib/python3.10/dist-packages/telegram/_bot.py", line 623, in _post
    return await self._do_post(
  File "/usr/local/lib/python3.10/dist-packages/telegram/ext/_extbot.py", line 355, in _do_post
    return await super()._do_post(
  File "/usr/local/lib/python3.10/dist-packages/telegram/_bot.py", line 652, in _do_post
    result = await request.post(
  File "/usr/local/lib/python3.10/dist-packages/telegram/request/_baserequest.py", line 201, in post
    result = await self._request_wrapper(
  File "/usr/local/lib/python3.10/dist-packages/telegram/request/_baserequest.py", line 384, in _request_wrapper
    raise Conflict(message)
telegram.error.Conflict: Conflict: terminated by other getUpdates request; make sure that only one bot instance is running
2025-07-16 23:09:19,496 - httpx - INFO - HTTP Request: POST https://api.telegram.org/bot7740411827:AAFl5Fb_tuntP-_KJ2TFa8IE96dSjkn9Lig/getUpdates "HTTP/1.1 409 Conflict"
2025-07-16 23:09:19,497 - telegram.ext.Application - ERROR - No error handlers are registered, logging exception.
Traceback (most recent call last):
  File "/usr/local/lib/python3.10/dist-packages/telegram/ext/_updater.py", line 753, in _network_loop_retry
    if not await do_action():
  File "/usr/local/lib/python3.10/dist-packages/telegram/ext/_updater.py", line 747, in do_action
    return action_cb_task.result()
  File "/usr/local/lib/python3.10/dist-packages/telegram/ext/_updater.py", line 377, in polling_action_cb
    updates = await self.bot.get_updates(
  File "/usr/local/lib/python3.10/dist-packages/telegram/ext/_extbot.py", line 649, in get_updates
    updates = await super().get_updates(
  File "/usr/local/lib/python3.10/dist-packages/telegram/_bot.py", line 4366, in get_updates
    await self._post(
  File "/usr/local/lib/python3.10/dist-packages/telegram/_bot.py", line 623, in _post
    return await self._do_post(
  File "/usr/local/lib/python3.10/dist-packages/telegram/ext/_extbot.py", line 355, in _do_post
    return await super()._do_post(
  File "/usr/local/lib/python3.10/dist-packages/telegram/_bot.py", line 652, in _do_post
    result = await request.post(
  File "/usr/local/lib/python3.10/dist-packages/telegram/request/_baserequest.py", line 201, in post
    result = await self._request_wrapper(
  File "/usr/local/lib/python3.10/dist-packages/telegram/request/_baserequest.py", line 384, in _request_wrapper
    raise Conflict(message)
telegram.error.Conflict: Conflict: terminated by other getUpdates request; make sure that only one bot instance is running
2025-07-16 23:09:53,590 - httpx - INFO - HTTP Request: POST https://api.telegram.org/bot7740411827:AAFl5Fb_tuntP-_KJ2TFa8IE96dSjkn9Lig/getUpdates "HTTP/1.1 409 Conflict"
2025-07-16 23:09:53,591 - telegram.ext.Application - ERROR - No error handlers are registered, logging exception.
Traceback (most recent call last):
  File "/usr/local/lib/python3.10/dist-packages/telegram/ext/_updater.py", line 753, in _network_loop_retry
    if not await do_action():
  File "/usr/local/lib/python3.10/dist-packages/telegram/ext/_updater.py", line 747, in do_action
    return action_cb_task.result()
  File "/usr/local/lib/python3.10/dist-packages/telegram/ext/_updater.py", line 377, in polling_action_cb
    updates = await self.bot.get_updates(
  File "/usr/local/lib/python3.10/dist-packages/telegram/ext/_extbot.py", line 649, in get_updates
    updates = await super().get_updates(
  File "/usr/local/lib/python3.10/dist-packages/telegram/_bot.py", line 4366, in get_updates
    await self._post(
  File "/usr/local/lib/python3.10/dist-packages/telegram/_bot.py", line 623, in _post
    return await self._do_post(
  File "/usr/local/lib/python3.10/dist-packages/telegram/ext/_extbot.py", line 355, in _do_post
    return await super()._do_post(
  File "/usr/local/lib/python3.10/dist-packages/telegram/_bot.py", line 652, in _do_post
    result = await request.post(
  File "/usr/local/lib/python3.10/dist-packages/telegram/request/_baserequest.py", line 201, in post
    result = await self._request_wrapper(
  File "/usr/local/lib/python3.10/dist-packages/telegram/request/_baserequest.py", line 384, in _request_wrapper
    raise Conflict(message)
telegram.error.Conflict: Conflict: terminated by other getUpdates request; make sure that only one bot instance is running
2025-07-16 23:10:27,682 - httpx - INFO - HTTP Request: POST https://api.telegram.org/bot7740411827:AAFl5Fb_tuntP-_KJ2TFa8IE96dSjkn9Lig/getUpdates "HTTP/1.1 409 Conflict"
2025-07-16 23:10:27,683 - telegram.ext.Application - ERROR - No error handlers are registered, logging exception.
Traceback (most recent call last):
  File "/usr/local/lib/python3.10/dist-packages/telegram/ext/_updater.py", line 753, in _network_loop_retry
    if not await do_action():
  File "/usr/local/lib/python3.10/dist-packages/telegram/ext/_updater.py", line 747, in do_action
    return action_cb_task.result()
  File "/usr/local/lib/python3.10/dist-packages/telegram/ext/_updater.py", line 377, in polling_action_cb
    updates = await self.bot.get_updates(
  File "/usr/local/lib/python3.10/dist-packages/telegram/ext/_extbot.py", line 649, in get_updates
    updates = await super().get_updates(
  File "/usr/local/lib/python3.10/dist-packages/telegram/_bot.py", line 4366, in get_updates
    await self._post(
  File "/usr/local/lib/python3.10/dist-packages/telegram/_bot.py", line 623, in _post
    return await self._do_post(
  File "/usr/local/lib/python3.10/dist-packages/telegram/ext/_extbot.py", line 355, in _do_post
    return await super()._do_post(
  File "/usr/local/lib/python3.10/dist-packages/telegram/_bot.py", line 652, in _do_post
    result = await request.post(
  File "/usr/local/lib/python3.10/dist-packages/telegram/request/_baserequest.py", line 201, in post
    result = await self._request_wrapper(
  File "/usr/local/lib/python3.10/dist-packages/telegram/request/_baserequest.py", line 384, in _request_wrapper
    raise Conflict(message)
telegram.error.Conflict: Conflict: terminated by other getUpdates request; make sure that only one bot instance is running
2025-07-16 23:11:01,767 - httpx - INFO - HTTP Request: POST https://api.telegram.org/bot7740411827:AAFl5Fb_tuntP-_KJ2TFa8IE96dSjkn9Lig/getUpdates "HTTP/1.1 409 Conflict"
2025-07-16 23:11:01,768 - telegram.ext.Application - ERROR - No error handlers are registered, logging exception.
Traceback (most recent call last):
  File "/usr/local/lib/python3.10/dist-packages/telegram/ext/_updater.py", line 753, in _network_loop_retry
    if not await do_action():
  File "/usr/local/lib/python3.10/dist-packages/telegram/ext/_updater.py", line 747, in do_action
    return action_cb_task.result()
  File "/usr/local/lib/python3.10/dist-packages/telegram/ext/_updater.py", line 377, in polling_action_cb
    updates = await self.bot.get_updates(
  File "/usr/local/lib/python3.10/dist-packages/telegram/ext/_extbot.py", line 649, in get_updates
    updates = await super().get_updates(
  File "/usr/local/lib/python3.10/dist-packages/telegram/_bot.py", line 4366, in get_updates
    await self._post(
  File "/usr/local/lib/python3.10/dist-packages/telegram/_bot.py", line 623, in _post
    return await self._do_post(
  File "/usr/local/lib/python3.10/dist-packages/telegram/ext/_extbot.py", line 355, in _do_post
    return await super()._do_post(
  File "/usr/local/lib/python3.10/dist-packages/telegram/_bot.py", line 652, in _do_post
    result = await request.post(
  File "/usr/local/lib/python3.10/dist-packages/telegram/request/_baserequest.py", line 201, in post
    result = await self._request_wrapper(
  File "/usr/local/lib/python3.10/dist-packages/telegram/request/_baserequest.py", line 384, in _request_wrapper
    raise Conflict(message)
telegram.error.Conflict: Conflict: terminated by other getUpdates request; make sure that only one bot instance is running
2025-07-16 23:11:35,865 - httpx - INFO - HTTP Request: POST https://api.telegram.org/bot7740411827:AAFl5Fb_tuntP-_KJ2TFa8IE96dSjkn9Lig/getUpdates "HTTP/1.1 409 Conflict"
2025-07-16 23:11:35,866 - telegram.ext.Application - ERROR - No error handlers are registered, logging exception.
Traceback (most recent call last):
  File "/usr/local/lib/python3.10/dist-packages/telegram/ext/_updater.py", line 753, in _network_loop_retry
    if not await do_action():
  File "/usr/local/lib/python3.10/dist-packages/telegram/ext/_updater.py", line 747, in do_action
    return action_cb_task.result()
  File "/usr/local/lib/python3.10/dist-packages/telegram/ext/_updater.py", line 377, in polling_action_cb
    updates = await self.bot.get_updates(
  File "/usr/local/lib/python3.10/dist-packages/telegram/ext/_extbot.py", line 649, in get_updates
    updates = await super().get_updates(
  File "/usr/local/lib/python3.10/dist-packages/telegram/_bot.py", line 4366, in get_updates
    await self._post(
  File "/usr/local/lib/python3.10/dist-packages/telegram/_bot.py", line 623, in _post
    return await self._do_post(
  File "/usr/local/lib/python3.10/dist-packages/telegram/ext/_extbot.py", line 355, in _do_post
    return await super()._do_post(
  File "/usr/local/lib/python3.10/dist-packages/telegram/_bot.py", line 652, in _do_post
    result = await request.post(
  File "/usr/local/lib/python3.10/dist-packages/telegram/request/_baserequest.py", line 201, in post
    result = await self._request_wrapper(
  File "/usr/local/lib/python3.10/dist-packages/telegram/request/_baserequest.py", line 384, in _request_wrapper
    raise Conflict(message)
telegram.error.Conflict: Conflict: terminated by other getUpdates request; make sure that only one bot instance is running
2025-07-16 23:12:09,960 - httpx - INFO - HTTP Request: POST https://api.telegram.org/bot7740411827:AAFl5Fb_tuntP-_KJ2TFa8IE96dSjkn9Lig/getUpdates "HTTP/1.1 409 Conflict"
2025-07-16 23:12:09,961 - telegram.ext.Application - ERROR - No error handlers are registered, logging exception.
Traceback (most recent call last):
  File "/usr/local/lib/python3.10/dist-packages/telegram/ext/_updater.py", line 753, in _network_loop_retry
    if not await do_action():
  File "/usr/local/lib/python3.10/dist-packages/telegram/ext/_updater.py", line 747, in do_action
    return action_cb_task.result()
  File "/usr/local/lib/python3.10/dist-packages/telegram/ext/_updater.py", line 377, in polling_action_cb
    updates = await self.bot.get_updates(
  File "/usr/local/lib/python3.10/dist-packages/telegram/ext/_extbot.py", line 649, in get_updates
    updates = await super().get_updates(
  File "/usr/local/lib/python3.10/dist-packages/telegram/_bot.py", line 4366, in get_updates
    await self._post(
  File "/usr/local/lib/python3.10/dist-packages/telegram/_bot.py", line 623, in _post
    return await self._do_post(
  File "/usr/local/lib/python3.10/dist-packages/telegram/ext/_extbot.py", line 355, in _do_post
    return await super()._do_post(
  File "/usr/local/lib/python3.10/dist-packages/telegram/_bot.py", line 652, in _do_post
    result = await request.post(
  File "/usr/local/lib/python3.10/dist-packages/telegram/request/_baserequest.py", line 201, in post
    result = await self._request_wrapper(
  File "/usr/local/lib/python3.10/dist-packages/telegram/request/_baserequest.py", line 384, in _request_wrapper
    raise Conflict(message)
telegram.error.Conflict: Conflict: terminated by other getUpdates request; make sure that only one bot instance is running
2025-07-16 23:12:44,052 - httpx - INFO - HTTP Request: POST https://api.telegram.org/bot7740411827:AAFl5Fb_tuntP-_KJ2TFa8IE96dSjkn9Lig/getUpdates "HTTP/1.1 409 Conflict"
2025-07-16 23:12:44,053 - telegram.ext.Application - ERROR - No error handlers are registered, logging exception.
Traceback (most recent call last):
  File "/usr/local/lib/python3.10/dist-packages/telegram/ext/_updater.py", line 753, in _network_loop_retry
    if not await do_action():
  File "/usr/local/lib/python3.10/dist-packages/telegram/ext/_updater.py", line 747, in do_action
    return action_cb_task.result()
  File "/usr/local/lib/python3.10/dist-packages/telegram/ext/_updater.py", line 377, in polling_action_cb
    updates = await self.bot.get_updates(
  File "/usr/local/lib/python3.10/dist-packages/telegram/ext/_extbot.py", line 649, in get_updates
    updates = await super().get_updates(
  File "/usr/local/lib/python3.10/dist-packages/telegram/_bot.py", line 4366, in get_updates
    await self._post(
  File "/usr/local/lib/python3.10/dist-packages/telegram/_bot.py", line 623, in _post
    return await self._do_post(
  File "/usr/local/lib/python3.10/dist-packages/telegram/ext/_extbot.py", line 355, in _do_post
    return await super()._do_post(
  File "/usr/local/lib/python3.10/dist-packages/telegram/_bot.py", line 652, in _do_post
    result = await request.post(
  File "/usr/local/lib/python3.10/dist-packages/telegram/request/_baserequest.py", line 201, in post
    result = await self._request_wrapper(
  File "/usr/local/lib/python3.10/dist-packages/telegram/request/_baserequest.py", line 384, in _request_wrapper
    raise Conflict(message)
telegram.error.Conflict: Conflict: terminated by other getUpdates request; make sure that only one bot instance is running
2025-07-16 23:13:18,117 - httpx - INFO - HTTP Request: POST https://api.telegram.org/bot7740411827:AAFl5Fb_tuntP-_KJ2TFa8IE96dSjkn9Lig/getUpdates "HTTP/1.1 409 Conflict"
2025-07-16 23:13:18,117 - telegram.ext.Application - ERROR - No error handlers are registered, logging exception.
Traceback (most recent call last):
  File "/usr/local/lib/python3.10/dist-packages/telegram/ext/_updater.py", line 753, in _network_loop_retry
    if not await do_action():
  File "/usr/local/lib/python3.10/dist-packages/telegram/ext/_updater.py", line 747, in do_action
    return action_cb_task.result()
  File "/usr/local/lib/python3.10/dist-packages/telegram/ext/_updater.py", line 377, in polling_action_cb
    updates = await self.bot.get_updates(
  File "/usr/local/lib/python3.10/dist-packages/telegram/ext/_extbot.py", line 649, in get_updates
    updates = await super().get_updates(
  File "/usr/local/lib/python3.10/dist-packages/telegram/_bot.py", line 4366, in get_updates
    await self._post(
  File "/usr/local/lib/python3.10/dist-packages/telegram/_bot.py", line 623, in _post
    return await self._do_post(
  File "/usr/local/lib/python3.10/dist-packages/telegram/ext/_extbot.py", line 355, in _do_post
    return await super()._do_post(
  File "/usr/local/lib/python3.10/dist-packages/telegram/_bot.py", line 652, in _do_post
    result = await request.post(
  File "/usr/local/lib/python3.10/dist-packages/telegram/request/_baserequest.py", line 201, in post
    result = await self._request_wrapper(
  File "/usr/local/lib/python3.10/dist-packages/telegram/request/_baserequest.py", line 384, in _request_wrapper
    raise Conflict(message)
telegram.error.Conflict: Conflict: terminated by other getUpdates request; make sure that only one bot instance is running
2025-07-16 23:13:52,213 - httpx - INFO - HTTP Request: POST https://api.telegram.org/bot7740411827:AAFl5Fb_tuntP-_KJ2TFa8IE96dSjkn9Lig/getUpdates "HTTP/1.1 409 Conflict"
2025-07-16 23:13:52,213 - telegram.ext.Application - ERROR - No error handlers are registered, logging exception.
Traceback (most recent call last):
  File "/usr/local/lib/python3.10/dist-packages/telegram/ext/_updater.py", line 753, in _network_loop_retry
    if not await do_action():
  File "/usr/local/lib/python3.10/dist-packages/telegram/ext/_updater.py", line 747, in do_action
    return action_cb_task.result()
  File "/usr/local/lib/python3.10/dist-packages/telegram/ext/_updater.py", line 377, in polling_action_cb
    updates = await self.bot.get_updates(
  File "/usr/local/lib/python3.10/dist-packages/telegram/ext/_extbot.py", line 649, in get_updates
    updates = await super().get_updates(
  File "/usr/local/lib/python3.10/dist-packages/telegram/_bot.py", line 4366, in get_updates
    await self._post(
  File "/usr/local/lib/python3.10/dist-packages/telegram/_bot.py", line 623, in _post
    return await self._do_post(
  File "/usr/local/lib/python3.10/dist-packages/telegram/ext/_extbot.py", line 355, in _do_post
    return await super()._do_post(
  File "/usr/local/lib/python3.10/dist-packages/telegram/_bot.py", line 652, in _do_post
    result = await request.post(
  File "/usr/local/lib/python3.10/dist-packages/telegram/request/_baserequest.py", line 201, in post
    result = await self._request_wrapper(
  File "/usr/local/lib/python3.10/dist-packages/telegram/request/_baserequest.py", line 384, in _request_wrapper
    raise Conflict(message)
telegram.error.Conflict: Conflict: terminated by other getUpdates request; make sure that only one bot instance is running
2025-07-16 23:14:25,407 - httpx - INFO - HTTP Request: POST https://api.telegram.org/bot7740411827:AAFl5Fb_tuntP-_KJ2TFa8IE96dSjkn9Lig/getUpdates "HTTP/1.1 409 Conflict"
2025-07-16 23:14:25,407 - telegram.ext.Application - ERROR - No error handlers are registered, logging exception.
Traceback (most recent call last):
  File "/usr/local/lib/python3.10/dist-packages/telegram/ext/_updater.py", line 753, in _network_loop_retry
    if not await do_action():
  File "/usr/local/lib/python3.10/dist-packages/telegram/ext/_updater.py", line 747, in do_action
    return action_cb_task.result()
  File "/usr/local/lib/python3.10/dist-packages/telegram/ext/_updater.py", line 377, in polling_action_cb
    updates = await self.bot.get_updates(
  File "/usr/local/lib/python3.10/dist-packages/telegram/ext/_extbot.py", line 649, in get_updates
    updates = await super().get_updates(
  File "/usr/local/lib/python3.10/dist-packages/telegram/_bot.py", line 4366, in get_updates
    await self._post(
  File "/usr/local/lib/python3.10/dist-packages/telegram/_bot.py", line 623, in _post
    return await self._do_post(
  File "/usr/local/lib/python3.10/dist-packages/telegram/ext/_extbot.py", line 355, in _do_post
    return await super()._do_post(
  File "/usr/local/lib/python3.10/dist-packages/telegram/_bot.py", line 652, in _do_post
    result = await request.post(
  File "/usr/local/lib/python3.10/dist-packages/telegram/request/_baserequest.py", line 201, in post
    result = await self._request_wrapper(
  File "/usr/local/lib/python3.10/dist-packages/telegram/request/_baserequest.py", line 384, in _request_wrapper
    raise Conflict(message)
telegram.error.Conflict: Conflict: terminated by other getUpdates request; make sure that only one bot instance is running
2025-07-16 23:14:59,494 - httpx - INFO - HTTP Request: POST https://api.telegram.org/bot7740411827:AAFl5Fb_tuntP-_KJ2TFa8IE96dSjkn9Lig/getUpdates "HTTP/1.1 409 Conflict"
2025-07-16 23:14:59,495 - telegram.ext.Application - ERROR - No error handlers are registered, logging exception.
Traceback (most recent call last):
  File "/usr/local/lib/python3.10/dist-packages/telegram/ext/_updater.py", line 753, in _network_loop_retry
    if not await do_action():
  File "/usr/local/lib/python3.10/dist-packages/telegram/ext/_updater.py", line 747, in do_action
    return action_cb_task.result()
  File "/usr/local/lib/python3.10/dist-packages/telegram/ext/_updater.py", line 377, in polling_action_cb
    updates = await self.bot.get_updates(
  File "/usr/local/lib/python3.10/dist-packages/telegram/ext/_extbot.py", line 649, in get_updates
    updates = await super().get_updates(
  File "/usr/local/lib/python3.10/dist-packages/telegram/_bot.py", line 4366, in get_updates
    await self._post(
  File "/usr/local/lib/python3.10/dist-packages/telegram/_bot.py", line 623, in _post
    return await self._do_post(
  File "/usr/local/lib/python3.10/dist-packages/telegram/ext/_extbot.py", line 355, in _do_post
    return await super()._do_post(
  File "/usr/local/lib/python3.10/dist-packages/telegram/_bot.py", line 652, in _do_post
    result = await request.post(
  File "/usr/local/lib/python3.10/dist-packages/telegram/request/_baserequest.py", line 201, in post
    result = await self._request_wrapper(
  File "/usr/local/lib/python3.10/dist-packages/telegram/request/_baserequest.py", line 384, in _request_wrapper
    raise Conflict(message)
telegram.error.Conflict: Conflict: terminated by other getUpdates request; make sure that only one bot instance is running
2025-07-16 23:15:29,557 - httpx - INFO - HTTP Request: POST https://api.telegram.org/bot7740411827:AAFl5Fb_tuntP-_KJ2TFa8IE96dSjkn9Lig/getUpdates "HTTP/1.1 200 OK"
2025-07-16 23:15:29,775 - httpx - INFO - HTTP Request: POST https://api.telegram.org/bot7740411827:AAFl5Fb_tuntP-_KJ2TFa8IE96dSjkn9Lig/sendMessage "HTTP/1.1 200 OK"
2025-07-16 23:15:39,577 - httpx - INFO - HTTP Request: POST https://api.telegram.org/bot7740411827:AAFl5Fb_tuntP-_KJ2TFa8IE96dSjkn9Lig/getUpdates "HTTP/1.1 200 OK"
2025-07-16 23:15:49,592 - httpx - INFO - HTTP Request: POST https://api.telegram.org/bot7740411827:AAFl5Fb_tuntP-_KJ2TFa8IE96dSjkn9Lig/getUpdates "HTTP/1.1 200 OK"
2025-07-16 23:15:55,297 - httpx - INFO - HTTP Request: POST https://api.telegram.org/bot7740411827:AAFl5Fb_tuntP-_KJ2TFa8IE96dSjkn9Lig/getUpdates "HTTP/1.1 200 OK"
2025-07-16 23:15:55,298 - telegram.ext.Application - INFO - Application is stopping. This might take a moment.
2025-07-16 23:15:55,298 - telegram.ext.Application - INFO - Application.stop() complete
2025-07-18 18:26:38,801 - __main__ - INFO - ‚úÖ Bot iniciado com sucesso - vers√£o com social links clic√°veis
2025-07-18 18:42:11,131 - __main__ - INFO - üîÑ Testing bot functionality - 18:42:11
2025-07-18 18:59:28,183 - __main__ - INFO - üîç TESTE: Verificando se bot est√° processando mensagens - 18:59:28
