2025-07-18 23:54:51,998 - bot - INFO - ü§ñ Bot de Similaridade iniciado!
2025-07-18 23:54:51,998 - bot - INFO - üìä Grupo de banco de dados: -4876022857
2025-07-18 23:54:51,998 - bot - INFO - üîç Grupo de compara√ß√£o: -1002725981594
2025-07-18 23:54:51,998 - bot - INFO - üîî Grupo de notifica√ß√£o: -1002807343035
2025-07-18 23:54:51,998 - bot - INFO - üìù Formato: Monospace ativado
2025-07-18 23:54:51,998 - bot - INFO - üîß Comandos dispon√≠veis: /database, /stats, /clear, /delete, /del, /threshold, /reset, /cas, /backup, /restore, /getid, /ailinks, /help
2025-07-18 23:54:52,042 - httpx - INFO - HTTP Request: POST https://api.telegram.org/bot7740411827:AAFl5Fb_tuntP-_KJ2TFa8IE96dSjkn9Lig/getMe "HTTP/1.1 200 OK"
2025-07-18 23:54:52,055 - httpx - INFO - HTTP Request: POST https://api.telegram.org/bot7740411827:AAFl5Fb_tuntP-_KJ2TFa8IE96dSjkn9Lig/deleteWebhook "HTTP/1.1 200 OK"
2025-07-18 23:54:52,056 - telegram.ext.Application - INFO - Application started
2025-07-18 23:54:57,313 - httpx - INFO - HTTP Request: POST https://api.telegram.org/bot7740411827:AAFl5Fb_tuntP-_KJ2TFa8IE96dSjkn9Lig/getUpdates "HTTP/1.1 409 Conflict"
2025-07-18 23:54:57,313 - telegram.ext.Updater - ERROR - Error while getting Updates: Conflict: terminated by other getUpdates request; make sure that only one bot instance is running
2025-07-18 23:54:57,313 - telegram.ext.Application - ERROR - No error handlers are registered, logging exception.
Traceback (most recent call last):
  File "/usr/local/lib/python3.10/dist-packages/telegram/ext/_updater.py", line 688, in _network_loop_retry
    if not await action_cb():
  File "/usr/local/lib/python3.10/dist-packages/telegram/ext/_updater.py", line 384, in polling_action_cb
    raise exc
  File "/usr/local/lib/python3.10/dist-packages/telegram/ext/_updater.py", line 373, in polling_action_cb
    updates = await self.bot.get_updates(
  File "/usr/local/lib/python3.10/dist-packages/telegram/ext/_extbot.py", line 558, in get_updates
    updates = await super().get_updates(
  File "/usr/local/lib/python3.10/dist-packages/telegram/_bot.py", line 525, in decorator
    result = await func(self, *args, **kwargs)  # skipcq: PYL-E1102
  File "/usr/local/lib/python3.10/dist-packages/telegram/_bot.py", line 3584, in get_updates
    await self._post(
  File "/usr/local/lib/python3.10/dist-packages/telegram/_bot.py", line 613, in _post
    return await self._do_post(
  File "/usr/local/lib/python3.10/dist-packages/telegram/ext/_extbot.py", line 340, in _do_post
    return await super()._do_post(
  File "/usr/local/lib/python3.10/dist-packages/telegram/_bot.py", line 641, in _do_post
    return await request.post(
  File "/usr/local/lib/python3.10/dist-packages/telegram/request/_baserequest.py", line 200, in post
    result = await self._request_wrapper(
  File "/usr/local/lib/python3.10/dist-packages/telegram/request/_baserequest.py", line 381, in _request_wrapper
    raise Conflict(message)
telegram.error.Conflict: Conflict: terminated by other getUpdates request; make sure that only one bot instance is running
2025-07-18 23:55:02,349 - httpx - INFO - HTTP Request: POST https://api.telegram.org/bot7740411827:AAFl5Fb_tuntP-_KJ2TFa8IE96dSjkn9Lig/getUpdates "HTTP/1.1 409 Conflict"
2025-07-18 23:55:02,349 - telegram.ext.Updater - ERROR - Error while getting Updates: Conflict: terminated by other getUpdates request; make sure that only one bot instance is running
2025-07-18 23:55:02,357 - telegram.ext.Application - ERROR - No error handlers are registered, logging exception.
Traceback (most recent call last):
  File "/usr/local/lib/python3.10/dist-packages/telegram/ext/_updater.py", line 688, in _network_loop_retry
    if not await action_cb():
  File "/usr/local/lib/python3.10/dist-packages/telegram/ext/_updater.py", line 384, in polling_action_cb
    raise exc
  File "/usr/local/lib/python3.10/dist-packages/telegram/ext/_updater.py", line 373, in polling_action_cb
    updates = await self.bot.get_updates(
  File "/usr/local/lib/python3.10/dist-packages/telegram/ext/_extbot.py", line 558, in get_updates
    updates = await super().get_updates(
  File "/usr/local/lib/python3.10/dist-packages/telegram/_bot.py", line 525, in decorator
    result = await func(self, *args, **kwargs)  # skipcq: PYL-E1102
  File "/usr/local/lib/python3.10/dist-packages/telegram/_bot.py", line 3584, in get_updates
    await self._post(
  File "/usr/local/lib/python3.10/dist-packages/telegram/_bot.py", line 613, in _post
    return await self._do_post(
  File "/usr/local/lib/python3.10/dist-packages/telegram/ext/_extbot.py", line 340, in _do_post
    return await super()._do_post(
  File "/usr/local/lib/python3.10/dist-packages/telegram/_bot.py", line 641, in _do_post
    return await request.post(
  File "/usr/local/lib/python3.10/dist-packages/telegram/request/_baserequest.py", line 200, in post
    result = await self._request_wrapper(
  File "/usr/local/lib/python3.10/dist-packages/telegram/request/_baserequest.py", line 381, in _request_wrapper
    raise Conflict(message)
telegram.error.Conflict: Conflict: terminated by other getUpdates request; make sure that only one bot instance is running
2025-07-18 23:55:08,412 - httpx - INFO - HTTP Request: POST https://api.telegram.org/bot7740411827:AAFl5Fb_tuntP-_KJ2TFa8IE96dSjkn9Lig/getUpdates "HTTP/1.1 409 Conflict"
2025-07-18 23:55:08,413 - telegram.ext.Updater - ERROR - Error while getting Updates: Conflict: terminated by other getUpdates request; make sure that only one bot instance is running
2025-07-18 23:55:08,413 - telegram.ext.Application - ERROR - No error handlers are registered, logging exception.
Traceback (most recent call last):
  File "/usr/local/lib/python3.10/dist-packages/telegram/ext/_updater.py", line 688, in _network_loop_retry
    if not await action_cb():
  File "/usr/local/lib/python3.10/dist-packages/telegram/ext/_updater.py", line 384, in polling_action_cb
    raise exc
  File "/usr/local/lib/python3.10/dist-packages/telegram/ext/_updater.py", line 373, in polling_action_cb
    updates = await self.bot.get_updates(
  File "/usr/local/lib/python3.10/dist-packages/telegram/ext/_extbot.py", line 558, in get_updates
    updates = await super().get_updates(
  File "/usr/local/lib/python3.10/dist-packages/telegram/_bot.py", line 525, in decorator
    result = await func(self, *args, **kwargs)  # skipcq: PYL-E1102
  File "/usr/local/lib/python3.10/dist-packages/telegram/_bot.py", line 3584, in get_updates
    await self._post(
  File "/usr/local/lib/python3.10/dist-packages/telegram/_bot.py", line 613, in _post
    return await self._do_post(
  File "/usr/local/lib/python3.10/dist-packages/telegram/ext/_extbot.py", line 340, in _do_post
    return await super()._do_post(
  File "/usr/local/lib/python3.10/dist-packages/telegram/_bot.py", line 641, in _do_post
    return await request.post(
  File "/usr/local/lib/python3.10/dist-packages/telegram/request/_baserequest.py", line 200, in post
    result = await self._request_wrapper(
  File "/usr/local/lib/python3.10/dist-packages/telegram/request/_baserequest.py", line 381, in _request_wrapper
    raise Conflict(message)
telegram.error.Conflict: Conflict: terminated by other getUpdates request; make sure that only one bot instance is running
2025-07-18 23:55:15,948 - httpx - INFO - HTTP Request: POST https://api.telegram.org/bot7740411827:AAFl5Fb_tuntP-_KJ2TFa8IE96dSjkn9Lig/getUpdates "HTTP/1.1 409 Conflict"
2025-07-18 23:55:15,949 - telegram.ext.Updater - ERROR - Error while getting Updates: Conflict: terminated by other getUpdates request; make sure that only one bot instance is running
2025-07-18 23:55:15,949 - telegram.ext.Application - ERROR - No error handlers are registered, logging exception.
Traceback (most recent call last):
  File "/usr/local/lib/python3.10/dist-packages/telegram/ext/_updater.py", line 688, in _network_loop_retry
    if not await action_cb():
  File "/usr/local/lib/python3.10/dist-packages/telegram/ext/_updater.py", line 384, in polling_action_cb
    raise exc
  File "/usr/local/lib/python3.10/dist-packages/telegram/ext/_updater.py", line 373, in polling_action_cb
    updates = await self.bot.get_updates(
  File "/usr/local/lib/python3.10/dist-packages/telegram/ext/_extbot.py", line 558, in get_updates
    updates = await super().get_updates(
  File "/usr/local/lib/python3.10/dist-packages/telegram/_bot.py", line 525, in decorator
    result = await func(self, *args, **kwargs)  # skipcq: PYL-E1102
  File "/usr/local/lib/python3.10/dist-packages/telegram/_bot.py", line 3584, in get_updates
    await self._post(
  File "/usr/local/lib/python3.10/dist-packages/telegram/_bot.py", line 613, in _post
    return await self._do_post(
  File "/usr/local/lib/python3.10/dist-packages/telegram/ext/_extbot.py", line 340, in _do_post
    return await super()._do_post(
  File "/usr/local/lib/python3.10/dist-packages/telegram/_bot.py", line 641, in _do_post
    return await request.post(
  File "/usr/local/lib/python3.10/dist-packages/telegram/request/_baserequest.py", line 200, in post
    result = await self._request_wrapper(
  File "/usr/local/lib/python3.10/dist-packages/telegram/request/_baserequest.py", line 381, in _request_wrapper
    raise Conflict(message)
telegram.error.Conflict: Conflict: terminated by other getUpdates request; make sure that only one bot instance is running
2025-07-18 23:55:22,744 - httpx - INFO - HTTP Request: POST https://api.telegram.org/bot7740411827:AAFl5Fb_tuntP-_KJ2TFa8IE96dSjkn9Lig/getUpdates "HTTP/1.1 409 Conflict"
2025-07-18 23:55:22,745 - telegram.ext.Updater - ERROR - Error while getting Updates: Conflict: terminated by other getUpdates request; make sure that only one bot instance is running
2025-07-18 23:55:22,753 - telegram.ext.Application - ERROR - No error handlers are registered, logging exception.
Traceback (most recent call last):
  File "/usr/local/lib/python3.10/dist-packages/telegram/ext/_updater.py", line 688, in _network_loop_retry
    if not await action_cb():
  File "/usr/local/lib/python3.10/dist-packages/telegram/ext/_updater.py", line 384, in polling_action_cb
    raise exc
  File "/usr/local/lib/python3.10/dist-packages/telegram/ext/_updater.py", line 373, in polling_action_cb
    updates = await self.bot.get_updates(
  File "/usr/local/lib/python3.10/dist-packages/telegram/ext/_extbot.py", line 558, in get_updates
    updates = await super().get_updates(
  File "/usr/local/lib/python3.10/dist-packages/telegram/_bot.py", line 525, in decorator
    result = await func(self, *args, **kwargs)  # skipcq: PYL-E1102
  File "/usr/local/lib/python3.10/dist-packages/telegram/_bot.py", line 3584, in get_updates
    await self._post(
  File "/usr/local/lib/python3.10/dist-packages/telegram/_bot.py", line 613, in _post
    return await self._do_post(
  File "/usr/local/lib/python3.10/dist-packages/telegram/ext/_extbot.py", line 340, in _do_post
    return await super()._do_post(
  File "/usr/local/lib/python3.10/dist-packages/telegram/_bot.py", line 641, in _do_post
    return await request.post(
  File "/usr/local/lib/python3.10/dist-packages/telegram/request/_baserequest.py", line 200, in post
    result = await self._request_wrapper(
  File "/usr/local/lib/python3.10/dist-packages/telegram/request/_baserequest.py", line 381, in _request_wrapper
    raise Conflict(message)
telegram.error.Conflict: Conflict: terminated by other getUpdates request; make sure that only one bot instance is running
2025-07-18 23:55:32,978 - httpx - INFO - HTTP Request: POST https://api.telegram.org/bot7740411827:AAFl5Fb_tuntP-_KJ2TFa8IE96dSjkn9Lig/getUpdates "HTTP/1.1 409 Conflict"
2025-07-18 23:55:32,979 - telegram.ext.Updater - ERROR - Error while getting Updates: Conflict: terminated by other getUpdates request; make sure that only one bot instance is running
2025-07-18 23:55:32,987 - telegram.ext.Application - ERROR - No error handlers are registered, logging exception.
Traceback (most recent call last):
  File "/usr/local/lib/python3.10/dist-packages/telegram/ext/_updater.py", line 688, in _network_loop_retry
    if not await action_cb():
  File "/usr/local/lib/python3.10/dist-packages/telegram/ext/_updater.py", line 384, in polling_action_cb
    raise exc
  File "/usr/local/lib/python3.10/dist-packages/telegram/ext/_updater.py", line 373, in polling_action_cb
    updates = await self.bot.get_updates(
  File "/usr/local/lib/python3.10/dist-packages/telegram/ext/_extbot.py", line 558, in get_updates
    updates = await super().get_updates(
  File "/usr/local/lib/python3.10/dist-packages/telegram/_bot.py", line 525, in decorator
    result = await func(self, *args, **kwargs)  # skipcq: PYL-E1102
  File "/usr/local/lib/python3.10/dist-packages/telegram/_bot.py", line 3584, in get_updates
    await self._post(
  File "/usr/local/lib/python3.10/dist-packages/telegram/_bot.py", line 613, in _post
    return await self._do_post(
  File "/usr/local/lib/python3.10/dist-packages/telegram/ext/_extbot.py", line 340, in _do_post
    return await super()._do_post(
  File "/usr/local/lib/python3.10/dist-packages/telegram/_bot.py", line 641, in _do_post
    return await request.post(
  File "/usr/local/lib/python3.10/dist-packages/telegram/request/_baserequest.py", line 200, in post
    result = await self._request_wrapper(
  File "/usr/local/lib/python3.10/dist-packages/telegram/request/_baserequest.py", line 381, in _request_wrapper
    raise Conflict(message)
telegram.error.Conflict: Conflict: terminated by other getUpdates request; make sure that only one bot instance is running
2025-07-18 23:55:48,275 - httpx - INFO - HTTP Request: POST https://api.telegram.org/bot7740411827:AAFl5Fb_tuntP-_KJ2TFa8IE96dSjkn9Lig/getUpdates "HTTP/1.1 409 Conflict"
2025-07-18 23:55:48,276 - telegram.ext.Updater - ERROR - Error while getting Updates: Conflict: terminated by other getUpdates request; make sure that only one bot instance is running
2025-07-18 23:55:48,276 - telegram.ext.Application - ERROR - No error handlers are registered, logging exception.
Traceback (most recent call last):
  File "/usr/local/lib/python3.10/dist-packages/telegram/ext/_updater.py", line 688, in _network_loop_retry
    if not await action_cb():
  File "/usr/local/lib/python3.10/dist-packages/telegram/ext/_updater.py", line 384, in polling_action_cb
    raise exc
  File "/usr/local/lib/python3.10/dist-packages/telegram/ext/_updater.py", line 373, in polling_action_cb
    updates = await self.bot.get_updates(
  File "/usr/local/lib/python3.10/dist-packages/telegram/ext/_extbot.py", line 558, in get_updates
    updates = await super().get_updates(
  File "/usr/local/lib/python3.10/dist-packages/telegram/_bot.py", line 525, in decorator
    result = await func(self, *args, **kwargs)  # skipcq: PYL-E1102
  File "/usr/local/lib/python3.10/dist-packages/telegram/_bot.py", line 3584, in get_updates
    await self._post(
  File "/usr/local/lib/python3.10/dist-packages/telegram/_bot.py", line 613, in _post
    return await self._do_post(
  File "/usr/local/lib/python3.10/dist-packages/telegram/ext/_extbot.py", line 340, in _do_post
    return await super()._do_post(
  File "/usr/local/lib/python3.10/dist-packages/telegram/_bot.py", line 641, in _do_post
    return await request.post(
  File "/usr/local/lib/python3.10/dist-packages/telegram/request/_baserequest.py", line 200, in post
    result = await self._request_wrapper(
  File "/usr/local/lib/python3.10/dist-packages/telegram/request/_baserequest.py", line 381, in _request_wrapper
    raise Conflict(message)
telegram.error.Conflict: Conflict: terminated by other getUpdates request; make sure that only one bot instance is running
2025-07-18 23:56:03,739 - httpx - INFO - HTTP Request: POST https://api.telegram.org/bot7740411827:AAFl5Fb_tuntP-_KJ2TFa8IE96dSjkn9Lig/getUpdates "HTTP/1.1 409 Conflict"
2025-07-18 23:56:03,739 - telegram.ext.Updater - ERROR - Error while getting Updates: Conflict: terminated by other getUpdates request; make sure that only one bot instance is running
2025-07-18 23:56:03,739 - telegram.ext.Application - ERROR - No error handlers are registered, logging exception.
Traceback (most recent call last):
  File "/usr/local/lib/python3.10/dist-packages/telegram/ext/_updater.py", line 688, in _network_loop_retry
    if not await action_cb():
  File "/usr/local/lib/python3.10/dist-packages/telegram/ext/_updater.py", line 384, in polling_action_cb
    raise exc
  File "/usr/local/lib/python3.10/dist-packages/telegram/ext/_updater.py", line 373, in polling_action_cb
    updates = await self.bot.get_updates(
  File "/usr/local/lib/python3.10/dist-packages/telegram/ext/_extbot.py", line 558, in get_updates
    updates = await super().get_updates(
  File "/usr/local/lib/python3.10/dist-packages/telegram/_bot.py", line 525, in decorator
    result = await func(self, *args, **kwargs)  # skipcq: PYL-E1102
  File "/usr/local/lib/python3.10/dist-packages/telegram/_bot.py", line 3584, in get_updates
    await self._post(
  File "/usr/local/lib/python3.10/dist-packages/telegram/_bot.py", line 613, in _post
    return await self._do_post(
  File "/usr/local/lib/python3.10/dist-packages/telegram/ext/_extbot.py", line 340, in _do_post
    return await super()._do_post(
  File "/usr/local/lib/python3.10/dist-packages/telegram/_bot.py", line 641, in _do_post
    return await request.post(
  File "/usr/local/lib/python3.10/dist-packages/telegram/request/_baserequest.py", line 200, in post
    result = await self._request_wrapper(
  File "/usr/local/lib/python3.10/dist-packages/telegram/request/_baserequest.py", line 381, in _request_wrapper
    raise Conflict(message)
telegram.error.Conflict: Conflict: terminated by other getUpdates request; make sure that only one bot instance is running
2025-07-18 23:56:24,906 - httpx - INFO - HTTP Request: POST https://api.telegram.org/bot7740411827:AAFl5Fb_tuntP-_KJ2TFa8IE96dSjkn9Lig/getUpdates "HTTP/1.1 409 Conflict"
2025-07-18 23:56:24,907 - telegram.ext.Updater - ERROR - Error while getting Updates: Conflict: terminated by other getUpdates request; make sure that only one bot instance is running
2025-07-18 23:56:24,907 - telegram.ext.Application - ERROR - No error handlers are registered, logging exception.
Traceback (most recent call last):
  File "/usr/local/lib/python3.10/dist-packages/telegram/ext/_updater.py", line 688, in _network_loop_retry
    if not await action_cb():
  File "/usr/local/lib/python3.10/dist-packages/telegram/ext/_updater.py", line 384, in polling_action_cb
    raise exc
  File "/usr/local/lib/python3.10/dist-packages/telegram/ext/_updater.py", line 373, in polling_action_cb
    updates = await self.bot.get_updates(
  File "/usr/local/lib/python3.10/dist-packages/telegram/ext/_extbot.py", line 558, in get_updates
    updates = await super().get_updates(
  File "/usr/local/lib/python3.10/dist-packages/telegram/_bot.py", line 525, in decorator
    result = await func(self, *args, **kwargs)  # skipcq: PYL-E1102
  File "/usr/local/lib/python3.10/dist-packages/telegram/_bot.py", line 3584, in get_updates
    await self._post(
  File "/usr/local/lib/python3.10/dist-packages/telegram/_bot.py", line 613, in _post
    return await self._do_post(
  File "/usr/local/lib/python3.10/dist-packages/telegram/ext/_extbot.py", line 340, in _do_post
    return await super()._do_post(
  File "/usr/local/lib/python3.10/dist-packages/telegram/_bot.py", line 641, in _do_post
    return await request.post(
  File "/usr/local/lib/python3.10/dist-packages/telegram/request/_baserequest.py", line 200, in post
    result = await self._request_wrapper(
  File "/usr/local/lib/python3.10/dist-packages/telegram/request/_baserequest.py", line 381, in _request_wrapper
    raise Conflict(message)
telegram.error.Conflict: Conflict: terminated by other getUpdates request; make sure that only one bot instance is running
2025-07-18 23:56:54,613 - httpx - INFO - HTTP Request: POST https://api.telegram.org/bot7740411827:AAFl5Fb_tuntP-_KJ2TFa8IE96dSjkn9Lig/getUpdates "HTTP/1.1 409 Conflict"
2025-07-18 23:56:54,614 - telegram.ext.Updater - ERROR - Error while getting Updates: Conflict: terminated by other getUpdates request; make sure that only one bot instance is running
2025-07-18 23:56:54,614 - telegram.ext.Application - ERROR - No error handlers are registered, logging exception.
Traceback (most recent call last):
  File "/usr/local/lib/python3.10/dist-packages/telegram/ext/_updater.py", line 688, in _network_loop_retry
    if not await action_cb():
  File "/usr/local/lib/python3.10/dist-packages/telegram/ext/_updater.py", line 384, in polling_action_cb
    raise exc
  File "/usr/local/lib/python3.10/dist-packages/telegram/ext/_updater.py", line 373, in polling_action_cb
    updates = await self.bot.get_updates(
  File "/usr/local/lib/python3.10/dist-packages/telegram/ext/_extbot.py", line 558, in get_updates
    updates = await super().get_updates(
  File "/usr/local/lib/python3.10/dist-packages/telegram/_bot.py", line 525, in decorator
    result = await func(self, *args, **kwargs)  # skipcq: PYL-E1102
  File "/usr/local/lib/python3.10/dist-packages/telegram/_bot.py", line 3584, in get_updates
    await self._post(
  File "/usr/local/lib/python3.10/dist-packages/telegram/_bot.py", line 613, in _post
    return await self._do_post(
  File "/usr/local/lib/python3.10/dist-packages/telegram/ext/_extbot.py", line 340, in _do_post
    return await super()._do_post(
  File "/usr/local/lib/python3.10/dist-packages/telegram/_bot.py", line 641, in _do_post
    return await request.post(
  File "/usr/local/lib/python3.10/dist-packages/telegram/request/_baserequest.py", line 200, in post
    result = await self._request_wrapper(
  File "/usr/local/lib/python3.10/dist-packages/telegram/request/_baserequest.py", line 381, in _request_wrapper
    raise Conflict(message)
telegram.error.Conflict: Conflict: terminated by other getUpdates request; make sure that only one bot instance is running
2025-07-18 23:57:28,684 - httpx - INFO - HTTP Request: POST https://api.telegram.org/bot7740411827:AAFl5Fb_tuntP-_KJ2TFa8IE96dSjkn9Lig/getUpdates "HTTP/1.1 409 Conflict"
2025-07-18 23:57:28,684 - telegram.ext.Updater - ERROR - Error while getting Updates: Conflict: terminated by other getUpdates request; make sure that only one bot instance is running
2025-07-18 23:57:28,685 - telegram.ext.Application - ERROR - No error handlers are registered, logging exception.
Traceback (most recent call last):
  File "/usr/local/lib/python3.10/dist-packages/telegram/ext/_updater.py", line 688, in _network_loop_retry
    if not await action_cb():
  File "/usr/local/lib/python3.10/dist-packages/telegram/ext/_updater.py", line 384, in polling_action_cb
    raise exc
  File "/usr/local/lib/python3.10/dist-packages/telegram/ext/_updater.py", line 373, in polling_action_cb
    updates = await self.bot.get_updates(
  File "/usr/local/lib/python3.10/dist-packages/telegram/ext/_extbot.py", line 558, in get_updates
    updates = await super().get_updates(
  File "/usr/local/lib/python3.10/dist-packages/telegram/_bot.py", line 525, in decorator
    result = await func(self, *args, **kwargs)  # skipcq: PYL-E1102
  File "/usr/local/lib/python3.10/dist-packages/telegram/_bot.py", line 3584, in get_updates
    await self._post(
  File "/usr/local/lib/python3.10/dist-packages/telegram/_bot.py", line 613, in _post
    return await self._do_post(
  File "/usr/local/lib/python3.10/dist-packages/telegram/ext/_extbot.py", line 340, in _do_post
    return await super()._do_post(
  File "/usr/local/lib/python3.10/dist-packages/telegram/_bot.py", line 641, in _do_post
    return await request.post(
  File "/usr/local/lib/python3.10/dist-packages/telegram/request/_baserequest.py", line 200, in post
    result = await self._request_wrapper(
  File "/usr/local/lib/python3.10/dist-packages/telegram/request/_baserequest.py", line 381, in _request_wrapper
    raise Conflict(message)
telegram.error.Conflict: Conflict: terminated by other getUpdates request; make sure that only one bot instance is running
2025-07-18 23:58:02,749 - httpx - INFO - HTTP Request: POST https://api.telegram.org/bot7740411827:AAFl5Fb_tuntP-_KJ2TFa8IE96dSjkn9Lig/getUpdates "HTTP/1.1 409 Conflict"
2025-07-18 23:58:02,750 - telegram.ext.Updater - ERROR - Error while getting Updates: Conflict: terminated by other getUpdates request; make sure that only one bot instance is running
2025-07-18 23:58:02,750 - telegram.ext.Application - ERROR - No error handlers are registered, logging exception.
Traceback (most recent call last):
  File "/usr/local/lib/python3.10/dist-packages/telegram/ext/_updater.py", line 688, in _network_loop_retry
    if not await action_cb():
  File "/usr/local/lib/python3.10/dist-packages/telegram/ext/_updater.py", line 384, in polling_action_cb
    raise exc
  File "/usr/local/lib/python3.10/dist-packages/telegram/ext/_updater.py", line 373, in polling_action_cb
    updates = await self.bot.get_updates(
  File "/usr/local/lib/python3.10/dist-packages/telegram/ext/_extbot.py", line 558, in get_updates
    updates = await super().get_updates(
  File "/usr/local/lib/python3.10/dist-packages/telegram/_bot.py", line 525, in decorator
    result = await func(self, *args, **kwargs)  # skipcq: PYL-E1102
  File "/usr/local/lib/python3.10/dist-packages/telegram/_bot.py", line 3584, in get_updates
    await self._post(
  File "/usr/local/lib/python3.10/dist-packages/telegram/_bot.py", line 613, in _post
    return await self._do_post(
  File "/usr/local/lib/python3.10/dist-packages/telegram/ext/_extbot.py", line 340, in _do_post
    return await super()._do_post(
  File "/usr/local/lib/python3.10/dist-packages/telegram/_bot.py", line 641, in _do_post
    return await request.post(
  File "/usr/local/lib/python3.10/dist-packages/telegram/request/_baserequest.py", line 200, in post
    result = await self._request_wrapper(
  File "/usr/local/lib/python3.10/dist-packages/telegram/request/_baserequest.py", line 381, in _request_wrapper
    raise Conflict(message)
telegram.error.Conflict: Conflict: terminated by other getUpdates request; make sure that only one bot instance is running
